<sdf version='1.4'>
  <world name='default'>
    <scene>
      <ambient>0.5 0.5 0.5 1</ambient>
      <background>0.5 0.5 0.5 1</background>
      <shadows>0</shadows>
    </scene>
    <physics type='ode'>
      <gravity>0 0 -9.8</gravity>
      <ode>
        <solver>
          <type>quick</type>
          <iters>10</iters>
          <sor>1.3</sor>
        </solver>
        <constraints>
          <cfm>0</cfm>
          <erp>0.2</erp>
          <contact_max_correcting_vel>100</contact_max_correcting_vel>
          <contact_surface_layer>0.001</contact_surface_layer>
        </constraints>
      </ode>
      <real_time_update_rate>1000</real_time_update_rate>
      <max_step_size>0.001</max_step_size>
      <real_time_factor>1</real_time_factor>
    </physics>
    <model name='ground_plane'>
      <static>1</static>
      <link name='link'>
        <collision name='collision'>
          <geometry>
            <plane>
              <normal>0 0 1</normal>
              <size>100 100</size>
            </plane>
          </geometry>
          <surface>
            <friction>
              <ode>
                <mu>100</mu>
                <mu2>50</mu2>
              </ode>
            </friction>
            <bounce/>
            <contact>
              <ode/>
            </contact>
          </surface>
          <max_contacts>10</max_contacts>
        </collision>
        <visual name='visual'>
          <cast_shadows>0</cast_shadows>
          <geometry>
            <plane>
              <normal>0 0 1</normal>
              <size>100 100</size>
            </plane>
          </geometry>
          <material>
            <script>
              <uri>file://media/materials/scripts/gazebo.material</uri>
              <name>Gazebo/Grey</name>
            </script>
          </material>
        </visual>
        <velocity_decay>
          <linear>0</linear>
          <angular>0</angular>
        </velocity_decay>
        <self_collide>0</self_collide>
        <kinematic>0</kinematic>
        <gravity>1</gravity>
      </link>
    </model>
    <light name='my_light' type='directional'>
      <pose>0 0 30 0 -0 0</pose>
      <diffuse>0.5 0.5 0.5 1</diffuse>
      <specular>0.1 0.1 0.1 1</specular>
      <attenuation>
        <range>200</range>
      </attenuation>
      <direction>0 0 -1</direction>
      <cast_shadows>0</cast_shadows>
    </light>
    <spherical_coordinates>
      <surface_model>EARTH_WGS84</surface_model>
      <latitude_deg>0</latitude_deg>
      <longitude_deg>0</longitude_deg>
      <elevation>0</elevation>
      <heading_deg>0</heading_deg>
    </spherical_coordinates>
    <model name='Gas Station'>
      <static>1</static>
      <link name='link'>
        <pose>0 0 0 0 -0 0</pose>
        <collision name='collision'>
          <geometry>
            <mesh>
              <uri>model://gas_station/meshes/gas_station.dae</uri>
            </mesh>
          </geometry>
          <max_contacts>10</max_contacts>
          <surface>
            <bounce/>
            <friction>
              <ode/>
            </friction>
            <contact>
              <ode/>
            </contact>
          </surface>
        </collision>
        <visual name='visual'>
          <geometry>
            <mesh>
              <uri>model://gas_station/meshes/gas_station.dae</uri>
            </mesh>
          </geometry>
          <material>
            <script>
              <uri>model://gas_station/materials/scripts</uri>
              <uri>model://gas_station/materials/textures</uri>
              <name>GasStation/Diffuse</name>
            </script>
            <shader type='normal_map_object_space'>
              <normal_map>GasStation_Normal.png</normal_map>
            </shader>
          </material>
        </visual>
        <velocity_decay>
          <linear>0</linear>
          <angular>0</angular>
        </velocity_decay>
        <self_collide>0</self_collide>
        <kinematic>0</kinematic>
        <gravity>1</gravity>
      </link>
      <pose>-7 10 0 0 -0 0</pose>
    </model>
    <state world_name='default'>
      <sim_time>179 575000000</sim_time>
      <real_time>99 575783059</real_time>
      <wall_time>1468273938 85031404</wall_time>
      <model name='Gas Station'>
        <pose>-7 10 0 0 -0 0</pose>
        <link name='link'>
          <pose>-7 10 0 0 -0 0</pose>
          <velocity>0 0 0 0 -0 0</velocity>
          <acceleration>0 0 0 0 -0 0</acceleration>
          <wrench>0 0 0 0 -0 0</wrench>
        </link>
      </model>
      <model name='Speed limit'>
        <pose>-3 -9 0 0 0 -1.56139</pose>
        <link name='link'>
          <pose>-3 -9 0 0 0 -1.56139</pose>
          <velocity>0 0 0 0 -0 0</velocity>
          <acceleration>0 0 0 0 -0 0</acceleration>
          <wrench>0 0 0 0 -0 0</wrench>
        </link>
      </model>
      <model name='Stop Sign'>
        <pose>2 4 -4e-06 -7.3e-05 -0.000144 1.65436e-24</pose>
        <link name='link'>
          <pose>2 4 -4e-06 -7.3e-05 -0.000144 1.65436e-24</pose>
          <velocity>0 0 0 0 -0 0</velocity>
          <acceleration>0 0 -9.8 -0 -0 -0.107938</acceleration>
          <wrench>0 0 -9.8 0 -0 0</wrench>
        </link>
      </model>
      <model name='ground_plane'>
        <pose>0 0 0 0 -0 0</pose>
        <link name='link'>
          <pose>0 0 0 0 -0 0</pose>
          <velocity>0 0 0 0 -0 0</velocity>
          <acceleration>0 0 0 0 -0 0</acceleration>
          <wrench>0 0 0 0 -0 0</wrench>
        </link>
      </model>
      <model name='ragdoll'>
        <pose>-3.00013 -7.99999 1.4 0 0.000802 -5.9e-05</pose>
        <link name='head'>
          <pose>-3.00001 -7.99999 2.625 0 -0 0</pose>
          <velocity>-0 1.7e-05 1.6e-05 5.1e-05 -0 0</velocity>
          <acceleration>-3e-06 0.003321 0.013177 -0.000733 -0 -0</acceleration>
          <wrench>-2.8e-05 0.033212 0.131774 0 -0 0</wrench>
        </link>
        <link name='hip'>
          <pose>-3.00013 -7.99999 1.4 0 0.000802 -5.9e-05</pose>
          <velocity>-1e-06 1.7e-05 2e-05 5e-06 5e-06 -3e-06</velocity>
          <acceleration>-3e-05 0.002225 0.011015 0.00025 2e-06 1.03398e-25</acceleration>
          <wrench>-0.000296 0.022249 0.110153 0 -0 0</wrench>
        </link>
        <link name='l_ankle'>
          <pose>-3.00019 -7.77999 0.074998 1e-06 -5e-06 -6.1e-05</pose>
          <velocity>-2.3e-05 0.000139 4.1e-05 0.000314 -0.000406 0.000234</velocity>
          <acceleration>0.001988 0.290708 0.004615 0.006589 0.000713 0.004453</acceleration>
          <wrench>0.001988 0.290708 0.004615 0 -0 0</wrench>
        </link>
        <link name='l_calf'>
          <pose>-2.99994 -7.77999 0.699997 1e-06 0.000395 -6.1e-05</pose>
          <velocity>-0 2e-06 3.1e-05 0.000273 3.7e-05 0.00015</velocity>
          <acceleration>0.000159 -0.0029 0.00904 0.005778 -3e-05 0.002783</acceleration>
          <wrench>0.000319 -0.005801 0.01808 0 -0 0</wrench>
        </link>
        <link name='l_foot'>
          <pose>-3.00019 -7.77999 0.05 -1.03398e-25 1.2e-05 -6.1e-05</pose>
          <velocity>-1.3e-05 0.000216 6e-05 -0.004326 -0.000261 0</velocity>
          <acceleration>0.000201 0.442138 -0.004451 -0.088429 4e-05 1e-06</acceleration>
          <wrench>0.000201 0.442138 -0.004451 0 -0 0</wrench>
        </link>
        <link name='l_forearm'>
          <pose>-3 -7.6725 1.7225 -6e-06 4e-06 -5.9e-05</pose>
          <velocity>0 8e-06 1.7e-05 -2.1e-05 -0 -3e-06</velocity>
          <acceleration>3e-06 -0.000756 0.012498 9e-06 -0 0</acceleration>
          <wrench>3e-06 -0.000756 0.012498 0 -0 0</wrench>
        </link>
        <link name='l_hand'>
          <pose>-3 -7.6725 1.24249 -6e-06 -0 -5.9e-05</pose>
          <velocity>0 -2e-06 1.7e-05 -2.1e-05 -0 -3e-06</velocity>
          <acceleration>0 0.000179 0.012614 1e-05 -0 0</acceleration>
          <wrench>0 0.000179 0.012614 0 -0 0</wrench>
        </link>
        <link name='l_shoulder'>
          <pose>-2.99996 -7.67249 2.32249 -6e-06 -8.4e-05 -5.9e-05</pose>
          <velocity>1e-06 2e-05 1.7e-05 -2e-05 -0 -3e-06</velocity>
          <acceleration>1.4e-05 -0.002841 0.012768 2.5e-05 -0 0</acceleration>
          <wrench>1.4e-05 -0.002841 0.012768 0 -0 0</wrench>
        </link>
        <link name='l_thigh_lift'>
          <pose>-3.00011 -7.77999 1.4 0 -0.000247 -6.1e-05</pose>
          <velocity>0 1.3e-05 2.6e-05 6.8e-05 -0 9.9e-05</velocity>
          <acceleration>-3e-05 -0.0037 0.01133 0.0017 -3e-06 0.001762</acceleration>
          <wrench>-0.000149 -0.018498 0.05665 0 -0 0</wrench>
        </link>
        <link name='l_thigh_pan'>
          <pose>-3.00011 -7.77999 1.4 0 0.000802 -6.1e-05</pose>
          <velocity>0 1.3e-05 2.6e-05 5.7e-05 5e-06 8.1e-05</velocity>
          <acceleration>-2.8e-05 -0.003334 0.011402 0.001502 2e-06 0.001398</acceleration>
          <wrench>-2.8e-05 -0.003334 0.011402 0 -0 0</wrench>
        </link>
        <link name='l_upper_arm'>
          <pose>-2.99996 -7.67249 2.32249 -6e-06 6.1e-05 -5.9e-05</pose>
          <velocity>1e-06 2e-05 1.7e-05 -2.1e-05 2e-06 -3e-06</velocity>
          <acceleration>1.4e-05 -0.002738 0.012743 2.3e-05 -0 0</acceleration>
          <wrench>2.8e-05 -0.005475 0.025486 0 -0 0</wrench>
        </link>
        <link name='l_wrist'>
          <pose>-3 -7.6725 1.2575 -6e-06 -0 -5.9e-05</pose>
          <velocity>0 -1e-06 1.7e-05 -2.1e-05 -0 -3e-06</velocity>
          <acceleration>0 0.000153 0.012508 8e-06 -0 0</acceleration>
          <wrench>0 0.000153 0.012508 0 -0 0</wrench>
        </link>
        <link name='neck'>
          <pose>-2.99998 -7.99999 2.34999 0 -8.4e-05 0</pose>
          <velocity>0 2.2e-05 1.5e-05 5.7e-05 -0 0</velocity>
          <acceleration>3e-06 -0.00358 0.012728 -0.000834 -0 -0</acceleration>
          <wrench>3e-06 -0.00358 0.012728 0 -0 0</wrench>
        </link>
        <link name='r_ankle'>
          <pose>-3.00019 -8.21999 0.074998 6.46235e-27 -2e-06 -2.1e-05</pose>
          <velocity>2e-06 1e-06 7.1e-05 -0.000256 -0.000199 -0.000388</velocity>
          <acceleration>0.032248 -0.319723 -0.009439 -0.008272 0.005088 -0.006833</acceleration>
          <wrench>0.032248 -0.319723 -0.009439 0 -0 0</wrench>
        </link>
        <link name='r_calf'>
          <pose>-2.99993 -8.21999 0.699997 -1.65436e-24 0.000407 -2.1e-05</pose>
          <velocity>4e-06 9.3e-05 4.8e-05 -0.000207 5e-06 -0.000143</velocity>
          <acceleration>0.000906 0.041959 -0.00962 -0.00755 -0.0005 -0.005011</acceleration>
          <wrench>0.001811 0.083919 -0.01924 0 -0 0</wrench>
        </link>
        <link name='r_foot'>
          <pose>-3.00019 -8.21999 0.05 -1e-06 1.5e-05 -2.1e-05</pose>
          <velocity>7e-06 -0.000152 0.000116 0.003073 0.000144 -8e-06</velocity>
          <acceleration>0.022721 -0.499771 -0.05443 0.100094 0.004555 -7.8e-05</acceleration>
          <wrench>0.022721 -0.499771 -0.05443 0 -0 0</wrench>
        </link>
        <link name='r_forearm'>
          <pose>-3 -8.3275 1.7225 -1e-05 -0 -5.9e-05</pose>
          <velocity>-0 1.1e-05 2e-05 -2.7e-05 -0 -3e-06</velocity>
          <acceleration>-1e-06 -0.00353 0.010853 7.1e-05 -0 0</acceleration>
          <wrench>-1e-06 -0.00353 0.010853 0 -0 0</wrench>
        </link>
        <link name='r_hand'>
          <pose>-3 -8.3275 1.24249 -1e-05 -0 -5.9e-05</pose>
          <velocity>-0 -3e-06 1.8e-05 -3.2e-05 -1.29247e-26 -3e-06</velocity>
          <acceleration>0 0.000854 0.009206 7.6e-05 -0 0</acceleration>
          <wrench>0 0.000854 0.009206 0 -0 0</wrench>
        </link>
        <link name='r_shoulder'>
          <pose>-3 -8.32749 2.32249 -1e-05 -8.4e-05 -5.9e-05</pose>
          <velocity>-1e-06 2.7e-05 2.2e-05 -2.9e-05 -1.29247e-26 -3e-06</velocity>
          <acceleration>-8e-06 -0.006152 0.011945 7.4e-05 -0 0</acceleration>
          <wrench>-8e-06 -0.006152 0.011945 0 -0 0</wrench>
        </link>
        <link name='r_thigh_lift'>
          <pose>-3.00014 -8.21999 1.4 8.27181e-25 -0.000291 -2.1e-05</pose>
          <velocity>-1e-06 2.1e-05 3.6e-05 3.8e-05 -8e-06 3.5e-05</velocity>
          <acceleration>-1.8e-05 0.013749 -0.009884 -0.001925 -1.1e-05 -0.003431</acceleration>
          <wrench>-9.2e-05 0.068747 -0.049422 0 -0 0</wrench>
        </link>
        <link name='r_thigh_pan'>
          <pose>-3.00014 -8.21999 1.4 0 0.000802 -2.1e-05</pose>
          <velocity>-1e-06 2.1e-05 2.9e-05 3.1e-05 5e-06 9.7e-05</velocity>
          <acceleration>-2e-05 0.014337 -0.018999 -0.002228 2e-06 -0.002844</acceleration>
          <wrench>-2e-05 0.014337 -0.018999 0 -0 0</wrench>
        </link>
        <link name='r_upper_arm'>
          <pose>-3 -8.32749 2.32249 -1e-05 -1e-06 -5.9e-05</pose>
          <velocity>-1e-06 2.8e-05 2e-05 -2.9e-05 -2e-06 -3e-06</velocity>
          <acceleration>-8e-06 -0.007056 0.011267 7.5e-05 -0 0</acceleration>
          <wrench>-1.6e-05 -0.014112 0.022534 0 -0 0</wrench>
        </link>
        <link name='r_wrist'>
          <pose>-3 -8.3275 1.2575 -1e-05 -0 -5.9e-05</pose>
          <velocity>-0 -2e-06 1.9e-05 -3.1e-05 1.29247e-26 -3e-06</velocity>
          <acceleration>0 0.000692 0.009922 8.7e-05 -0 0</acceleration>
          <wrench>0 0.000692 0.009922 0 -0 0</wrench>
        </link>
        <link name='torso'>
          <pose>-2.99993 -7.99999 1.65 -8.27181e-25 -8.4e-05 -5.9e-05</pose>
          <velocity>0 2e-05 1.9e-05 -7e-06 -0 -3e-06</velocity>
          <acceleration>1.6e-05 -0.002777 0.013308 4.5e-05 -0 0</acceleration>
          <wrench>0.000476 -0.083316 0.399252 0 -0 0</wrench>
        </link>
      </model>
    </state>
    <gui fullscreen='0'>
      <camera name='user_camera'>
        <pose>15.7787 -7.49647 7.00977 0 0.315643 2.86419</pose>
        <view_controller>orbit</view_controller>
      </camera>
    </gui>
    <model name='ragdoll'>
      <pose>-3 -8 1.4 0 -0 0</pose>
      <link name='hip'>
        <inertial>
          <inertia>
            <ixx>0.1</ixx>
            <ixy>0</ixy>
            <ixz>0</ixz>
            <iyy>0.1</iyy>
            <iyz>0</iyz>
            <izz>0.1</izz>
          </inertia>
          <mass>10</mass>
        </inertial>
        <collision name='hip_geom'>
          <pose>0 0 0.125 0 -0 0</pose>
          <geometry>
            <box>
              <size>0.1 0.5 0.25</size>
            </box>
          </geometry>
          <surface>
            <friction>
              <ode>
                <mu>-1</mu>
                <mu2>-1</mu2>
                <fdir1>0 0 0</fdir1>
                <slip1>0</slip1>
                <slip2>0</slip2>
              </ode>
            </friction>
            <bounce>
              <restitution_coefficient>0</restitution_coefficient>
              <threshold>100000</threshold>
            </bounce>
            <contact>
              <ode>
                <soft_cfm>0</soft_cfm>
                <soft_erp>0.2</soft_erp>
                <kp>1e+12</kp>
                <kd>1</kd>
                <max_vel>0</max_vel>
                <min_depth>0.001</min_depth>
              </ode>
            </contact>
          </surface>
          <laser_retro>0</laser_retro>
          <max_contacts>10</max_contacts>
        </collision>
        <visual name='hip_geom_visual'>
          <pose>0 0 0.125 0 -0 0</pose>
          <geometry>
            <box>
              <size>0.1 0.5 0.25</size>
            </box>
          </geometry>
          <cast_shadows>1</cast_shadows>
          <laser_retro>0</laser_retro>
          <transparency>0</transparency>
        </visual>
        <gravity>0</gravity>
        <self_collide>0</self_collide>
        <kinematic>0</kinematic>
        <velocity_decay>
          <linear>0</linear>
          <angular>0</angular>
        </velocity_decay>
      </link>
      <link name='l_thigh_pan'>
        <pose>0 0.22 0 0 -0 0</pose>
        <inertial>
          <inertia>
            <ixx>0.01</ixx>
            <ixy>0</ixy>
            <ixz>0</ixz>
            <iyy>0.01</iyy>
            <iyz>0</iyz>
            <izz>0.01</izz>
          </inertia>
          <mass>1</mass>
        </inertial>
        <collision name='l_thigh_pan_geom'>
          <pose>0 0 -0.03 0 -0 0</pose>
          <geometry>
            <sphere>
              <radius>0.06</radius>
            </sphere>
          </geometry>
          <surface>
            <friction>
              <ode>
                <mu>-1</mu>
                <mu2>-1</mu2>
                <fdir1>0 0 0</fdir1>
                <slip1>0</slip1>
                <slip2>0</slip2>
              </ode>
            </friction>
            <bounce>
              <restitution_coefficient>0</restitution_coefficient>
              <threshold>100000</threshold>
            </bounce>
            <contact>
              <ode>
                <soft_cfm>0</soft_cfm>
                <soft_erp>0.2</soft_erp>
                <kp>1e+12</kp>
                <kd>1</kd>
                <max_vel>0</max_vel>
                <min_depth>0.001</min_depth>
              </ode>
            </contact>
          </surface>
          <laser_retro>0</laser_retro>
          <max_contacts>10</max_contacts>
        </collision>
        <visual name='l_thigh_pan_geom_visual'>
          <pose>0 0 -0.03 0 -0 0</pose>
          <geometry>
            <sphere>
              <radius>0.06</radius>
            </sphere>
          </geometry>
          <cast_shadows>1</cast_shadows>
          <laser_retro>0</laser_retro>
          <transparency>0</transparency>
        </visual>
        <gravity>0</gravity>
        <self_collide>0</self_collide>
        <kinematic>0</kinematic>
        <velocity_decay>
          <linear>0</linear>
          <angular>0</angular>
        </velocity_decay>
      </link>
      <link name='l_thigh_lift'>
        <pose>0 0.22 0 0 -0 0</pose>
        <inertial>
          <inertia>
            <ixx>0.05</ixx>
            <ixy>0</ixy>
            <ixz>0</ixz>
            <iyy>0.05</iyy>
            <iyz>0</iyz>
            <izz>0.05</izz>
          </inertia>
          <mass>5</mass>
        </inertial>
        <collision name='l_thigh_lift_geom'>
          <pose>0 0 -0.35 0 -0 0</pose>
          <geometry>
            <cylinder>
              <radius>0.06</radius>
              <length>0.7</length>
            </cylinder>
          </geometry>
          <surface>
            <friction>
              <ode>
                <mu>-1</mu>
                <mu2>-1</mu2>
                <fdir1>0 0 0</fdir1>
                <slip1>0</slip1>
                <slip2>0</slip2>
              </ode>
            </friction>
            <bounce>
              <restitution_coefficient>0</restitution_coefficient>
              <threshold>100000</threshold>
            </bounce>
            <contact>
              <ode>
                <soft_cfm>0</soft_cfm>
                <soft_erp>0.2</soft_erp>
                <kp>1e+12</kp>
                <kd>1</kd>
                <max_vel>0</max_vel>
                <min_depth>0.001</min_depth>
              </ode>
            </contact>
          </surface>
          <laser_retro>0</laser_retro>
          <max_contacts>10</max_contacts>
        </collision>
        <visual name='l_thigh_lift_geom_visual'>
          <pose>0 0 -0.35 0 -0 0</pose>
          <geometry>
            <cylinder>
              <radius>0.06</radius>
              <length>0.7</length>
            </cylinder>
          </geometry>
          <cast_shadows>1</cast_shadows>
          <laser_retro>0</laser_retro>
          <transparency>0</transparency>
        </visual>
        <gravity>0</gravity>
        <self_collide>0</self_collide>
        <kinematic>0</kinematic>
        <velocity_decay>
          <linear>0</linear>
          <angular>0</angular>
        </velocity_decay>
      </link>
      <link name='l_calf'>
        <pose>0 0.22 -0.7 0 -0 0</pose>
        <inertial>
          <inertia>
            <ixx>0.02</ixx>
            <ixy>0</ixy>
            <ixz>0</ixz>
            <iyy>0.02</iyy>
            <iyz>0</iyz>
            <izz>0.02</izz>
          </inertia>
          <mass>2</mass>
        </inertial>
        <collision name='l_calf_geom'>
          <pose>0 0 -0.3 0 -0 0</pose>
          <geometry>
            <cylinder>
              <radius>0.05</radius>
              <length>0.6</length>
            </cylinder>
          </geometry>
          <surface>
            <friction>
              <ode>
                <mu>-1</mu>
                <mu2>-1</mu2>
                <fdir1>0 0 0</fdir1>
                <slip1>0</slip1>
                <slip2>0</slip2>
              </ode>
            </friction>
            <bounce>
              <restitution_coefficient>0</restitution_coefficient>
              <threshold>100000</threshold>
            </bounce>
            <contact>
              <ode>
                <soft_cfm>0</soft_cfm>
                <soft_erp>0.2</soft_erp>
                <kp>1e+12</kp>
                <kd>1</kd>
                <max_vel>0</max_vel>
                <min_depth>0.001</min_depth>
              </ode>
            </contact>
          </surface>
          <laser_retro>0</laser_retro>
          <max_contacts>10</max_contacts>
        </collision>
        <visual name='l_calf_geom_visual'>
          <pose>0 0 -0.3 0 -0 0</pose>
          <geometry>
            <cylinder>
              <radius>0.05</radius>
              <length>0.6</length>
            </cylinder>
          </geometry>
          <cast_shadows>1</cast_shadows>
          <laser_retro>0</laser_retro>
          <transparency>0</transparency>
        </visual>
        <gravity>0</gravity>
        <self_collide>0</self_collide>
        <kinematic>0</kinematic>
        <velocity_decay>
          <linear>0</linear>
          <angular>0</angular>
        </velocity_decay>
      </link>
      <link name='l_ankle'>
        <pose>0 0.22 -1.325 0 -0 0</pose>
        <inertial>
          <inertia>
            <ixx>0.01</ixx>
            <ixy>0</ixy>
            <ixz>0</ixz>
            <iyy>0.01</iyy>
            <iyz>0</iyz>
            <izz>0.01</izz>
          </inertia>
          <mass>1</mass>
        </inertial>
        <collision name='l_ankle_geom'>
          <geometry>
            <sphere>
              <radius>0.05</radius>
            </sphere>
          </geometry>
          <surface>
            <friction>
              <ode>
                <mu>-1</mu>
                <mu2>-1</mu2>
                <fdir1>0 0 0</fdir1>
                <slip1>0</slip1>
                <slip2>0</slip2>
              </ode>
            </friction>
            <bounce>
              <restitution_coefficient>0</restitution_coefficient>
              <threshold>100000</threshold>
            </bounce>
            <contact>
              <ode>
                <soft_cfm>0</soft_cfm>
                <soft_erp>0.2</soft_erp>
                <kp>1e+12</kp>
                <kd>1</kd>
                <max_vel>0</max_vel>
                <min_depth>0.001</min_depth>
              </ode>
            </contact>
          </surface>
          <laser_retro>0</laser_retro>
          <max_contacts>10</max_contacts>
        </collision>
        <visual name='l_ankle_geom_visual'>
          <geometry>
            <sphere>
              <radius>0.05</radius>
            </sphere>
          </geometry>
          <cast_shadows>1</cast_shadows>
          <laser_retro>0</laser_retro>
          <transparency>0</transparency>
        </visual>
        <gravity>0</gravity>
        <self_collide>0</self_collide>
        <kinematic>0</kinematic>
        <velocity_decay>
          <linear>0</linear>
          <angular>0</angular>
        </velocity_decay>
      </link>
      <link name='l_foot'>
        <pose>0 0.22 -1.35 0 -0 0</pose>
        <inertial>
          <pose>0.1 0 0 0 -0 0</pose>
          <inertia>
            <ixx>0.01</ixx>
            <ixy>0</ixy>
            <ixz>0</ixz>
            <iyy>0.01</iyy>
            <iyz>0</iyz>
            <izz>0.01</izz>
          </inertia>
          <mass>1</mass>
        </inertial>
        <collision name='l_foot_geom'>
          <pose>0.1 0 -0.025 0 -0 0</pose>
          <geometry>
            <box>
              <size>0.2 0.03 0.05</size>
            </box>
          </geometry>
          <surface>
            <friction>
              <ode>
                <mu>-1</mu>
                <mu2>-1</mu2>
                <fdir1>0 0 0</fdir1>
                <slip1>0</slip1>
                <slip2>0</slip2>
              </ode>
            </friction>
            <bounce>
              <restitution_coefficient>0</restitution_coefficient>
              <threshold>100000</threshold>
            </bounce>
            <contact>
              <ode>
                <soft_cfm>0</soft_cfm>
                <soft_erp>0.2</soft_erp>
                <kp>1e+12</kp>
                <kd>1</kd>
                <max_vel>0</max_vel>
                <min_depth>0.001</min_depth>
              </ode>
            </contact>
          </surface>
          <laser_retro>0</laser_retro>
          <max_contacts>10</max_contacts>
        </collision>
        <visual name='l_foot_geom_visual'>
          <pose>0.1 0 -0.025 0 -0 0</pose>
          <geometry>
            <box>
              <size>0.2 0.03 0.05</size>
            </box>
          </geometry>
          <cast_shadows>1</cast_shadows>
          <laser_retro>0</laser_retro>
          <transparency>0</transparency>
        </visual>
        <gravity>1</gravity>
        <self_collide>0</self_collide>
        <kinematic>0</kinematic>
        <velocity_decay>
          <linear>0</linear>
          <angular>0</angular>
        </velocity_decay>
      </link>
      <link name='r_thigh_pan'>
        <pose>0 -0.22 0 0 -0 0</pose>
        <inertial>
          <inertia>
            <ixx>0.01</ixx>
            <ixy>0</ixy>
            <ixz>0</ixz>
            <iyy>0.01</iyy>
            <iyz>0</iyz>
            <izz>0.01</izz>
          </inertia>
          <mass>1</mass>
        </inertial>
        <collision name='r_thigh_pan_geom'>
          <pose>0 0 -0.03 0 -0 0</pose>
          <geometry>
            <sphere>
              <radius>0.06</radius>
            </sphere>
          </geometry>
          <surface>
            <friction>
              <ode>
                <mu>-1</mu>
                <mu2>-1</mu2>
                <fdir1>0 0 0</fdir1>
                <slip1>0</slip1>
                <slip2>0</slip2>
              </ode>
            </friction>
            <bounce>
              <restitution_coefficient>0</restitution_coefficient>
              <threshold>100000</threshold>
            </bounce>
            <contact>
              <ode>
                <soft_cfm>0</soft_cfm>
                <soft_erp>0.2</soft_erp>
                <kp>1e+12</kp>
                <kd>1</kd>
                <max_vel>0</max_vel>
                <min_depth>0.001</min_depth>
              </ode>
            </contact>
          </surface>
          <laser_retro>0</laser_retro>
          <max_contacts>10</max_contacts>
        </collision>
        <visual name='r_thigh_pan_geom_visual'>
          <pose>0 0 -0.03 0 -0 0</pose>
          <geometry>
            <sphere>
              <radius>0.06</radius>
            </sphere>
          </geometry>
          <cast_shadows>1</cast_shadows>
          <laser_retro>0</laser_retro>
          <transparency>0</transparency>
        </visual>
        <gravity>0</gravity>
        <self_collide>0</self_collide>
        <kinematic>0</kinematic>
        <velocity_decay>
          <linear>0</linear>
          <angular>0</angular>
        </velocity_decay>
      </link>
      <link name='r_thigh_lift'>
        <pose>0 -0.22 0 0 -0 0</pose>
        <inertial>
          <inertia>
            <ixx>0.05</ixx>
            <ixy>0</ixy>
            <ixz>0</ixz>
            <iyy>0.05</iyy>
            <iyz>0</iyz>
            <izz>0.05</izz>
          </inertia>
          <mass>5</mass>
        </inertial>
        <collision name='r_thigh_lift_geom'>
          <pose>0 0 -0.35 0 -0 0</pose>
          <geometry>
            <cylinder>
              <radius>0.06</radius>
              <length>0.7</length>
            </cylinder>
          </geometry>
          <surface>
            <friction>
              <ode>
                <mu>-1</mu>
                <mu2>-1</mu2>
                <fdir1>0 0 0</fdir1>
                <slip1>0</slip1>
                <slip2>0</slip2>
              </ode>
            </friction>
            <bounce>
              <restitution_coefficient>0</restitution_coefficient>
              <threshold>100000</threshold>
            </bounce>
            <contact>
              <ode>
                <soft_cfm>0</soft_cfm>
                <soft_erp>0.2</soft_erp>
                <kp>1e+12</kp>
                <kd>1</kd>
                <max_vel>0</max_vel>
                <min_depth>0.001</min_depth>
              </ode>
            </contact>
          </surface>
          <laser_retro>0</laser_retro>
          <max_contacts>10</max_contacts>
        </collision>
        <visual name='r_thigh_lift_geom_visual'>
          <pose>0 0 -0.35 0 -0 0</pose>
          <geometry>
            <cylinder>
              <radius>0.06</radius>
              <length>0.7</length>
            </cylinder>
          </geometry>
          <cast_shadows>1</cast_shadows>
          <laser_retro>0</laser_retro>
          <transparency>0</transparency>
        </visual>
        <gravity>0</gravity>
        <self_collide>0</self_collide>
        <kinematic>0</kinematic>
        <velocity_decay>
          <linear>0</linear>
          <angular>0</angular>
        </velocity_decay>
      </link>
      <link name='r_calf'>
        <pose>0 -0.22 -0.7 0 -0 0</pose>
        <inertial>
          <inertia>
            <ixx>0.02</ixx>
            <ixy>0</ixy>
            <ixz>0</ixz>
            <iyy>0.02</iyy>
            <iyz>0</iyz>
            <izz>0.02</izz>
          </inertia>
          <mass>2</mass>
        </inertial>
        <collision name='r_calf_geom'>
          <pose>0 0 -0.3 0 -0 0</pose>
          <geometry>
            <cylinder>
              <radius>0.05</radius>
              <length>0.6</length>
            </cylinder>
          </geometry>
          <surface>
            <friction>
              <ode>
                <mu>-1</mu>
                <mu2>-1</mu2>
                <fdir1>0 0 0</fdir1>
                <slip1>0</slip1>
                <slip2>0</slip2>
              </ode>
            </friction>
            <bounce>
              <restitution_coefficient>0</restitution_coefficient>
              <threshold>100000</threshold>
            </bounce>
            <contact>
              <ode>
                <soft_cfm>0</soft_cfm>
                <soft_erp>0.2</soft_erp>
                <kp>1e+12</kp>
                <kd>1</kd>
                <max_vel>0</max_vel>
                <min_depth>0.001</min_depth>
              </ode>
            </contact>
          </surface>
          <laser_retro>0</laser_retro>
          <max_contacts>10</max_contacts>
        </collision>
        <visual name='r_calf_geom_visual'>
          <pose>0 0 -0.3 0 -0 0</pose>
          <geometry>
            <cylinder>
              <radius>0.05</radius>
              <length>0.6</length>
            </cylinder>
          </geometry>
          <cast_shadows>1</cast_shadows>
          <laser_retro>0</laser_retro>
          <transparency>0</transparency>
        </visual>
        <gravity>0</gravity>
        <self_collide>0</self_collide>
        <kinematic>0</kinematic>
        <velocity_decay>
          <linear>0</linear>
          <angular>0</angular>
        </velocity_decay>
      </link>
      <link name='r_ankle'>
        <pose>0 -0.22 -1.325 0 -0 0</pose>
        <inertial>
          <inertia>
            <ixx>0.01</ixx>
            <ixy>0</ixy>
            <ixz>0</ixz>
            <iyy>0.01</iyy>
            <iyz>0</iyz>
            <izz>0.01</izz>
          </inertia>
          <mass>1</mass>
        </inertial>
        <collision name='r_ankle_geom'>
          <geometry>
            <sphere>
              <radius>0.05</radius>
            </sphere>
          </geometry>
          <surface>
            <friction>
              <ode>
                <mu>-1</mu>
                <mu2>-1</mu2>
                <fdir1>0 0 0</fdir1>
                <slip1>0</slip1>
                <slip2>0</slip2>
              </ode>
            </friction>
            <bounce>
              <restitution_coefficient>0</restitution_coefficient>
              <threshold>100000</threshold>
            </bounce>
            <contact>
              <ode>
                <soft_cfm>0</soft_cfm>
                <soft_erp>0.2</soft_erp>
                <kp>1e+12</kp>
                <kd>1</kd>
                <max_vel>0</max_vel>
                <min_depth>0.001</min_depth>
              </ode>
            </contact>
          </surface>
          <laser_retro>0</laser_retro>
          <max_contacts>10</max_contacts>
        </collision>
        <visual name='r_ankle_geom_visual'>
          <geometry>
            <sphere>
              <radius>0.05</radius>
            </sphere>
          </geometry>
          <cast_shadows>1</cast_shadows>
          <laser_retro>0</laser_retro>
          <transparency>0</transparency>
        </visual>
        <gravity>0</gravity>
        <self_collide>0</self_collide>
        <kinematic>0</kinematic>
        <velocity_decay>
          <linear>0</linear>
          <angular>0</angular>
        </velocity_decay>
      </link>
      <link name='r_foot'>
        <pose>0 -0.22 -1.35 0 -0 0</pose>
        <inertial>
          <pose>0.1 0 0 0 -0 0</pose>
          <inertia>
            <ixx>0.01</ixx>
            <ixy>0</ixy>
            <ixz>0</ixz>
            <iyy>0.01</iyy>
            <iyz>0</iyz>
            <izz>0.01</izz>
          </inertia>
          <mass>1</mass>
        </inertial>
        <collision name='r_foot_geom'>
          <pose>0.1 0 -0.025 0 -0 0</pose>
          <geometry>
            <box>
              <size>0.2 0.03 0.05</size>
            </box>
          </geometry>
          <surface>
            <friction>
              <ode>
                <mu>-1</mu>
                <mu2>-1</mu2>
                <fdir1>0 0 0</fdir1>
                <slip1>0</slip1>
                <slip2>0</slip2>
              </ode>
            </friction>
            <bounce>
              <restitution_coefficient>0</restitution_coefficient>
              <threshold>100000</threshold>
            </bounce>
            <contact>
              <ode>
                <soft_cfm>0</soft_cfm>
                <soft_erp>0.2</soft_erp>
                <kp>1e+12</kp>
                <kd>1</kd>
                <max_vel>0</max_vel>
                <min_depth>0.001</min_depth>
              </ode>
            </contact>
          </surface>
          <laser_retro>0</laser_retro>
          <max_contacts>10</max_contacts>
        </collision>
        <visual name='r_foot_geom_visual'>
          <pose>0.1 0 -0.025 0 -0 0</pose>
          <geometry>
            <box>
              <size>0.2 0.03 0.05</size>
            </box>
          </geometry>
          <cast_shadows>1</cast_shadows>
          <laser_retro>0</laser_retro>
          <transparency>0</transparency>
        </visual>
        <gravity>1</gravity>
        <self_collide>0</self_collide>
        <kinematic>0</kinematic>
        <velocity_decay>
          <linear>0</linear>
          <angular>0</angular>
        </velocity_decay>
      </link>
      <link name='torso'>
        <pose>0 0 0.25 0 -0 0</pose>
        <inertial>
          <inertia>
            <ixx>0.3</ixx>
            <ixy>0</ixy>
            <ixz>0</ixz>
            <iyy>0.3</iyy>
            <iyz>0</iyz>
            <izz>0.3</izz>
          </inertia>
          <mass>30</mass>
        </inertial>
        <collision name='torso_geom'>
          <pose>0 0 0.35 0 -0 0</pose>
          <geometry>
            <box>
              <size>0.1 0.6 0.7</size>
            </box>
          </geometry>
          <surface>
            <friction>
              <ode>
                <mu>-1</mu>
                <mu2>-1</mu2>
                <fdir1>0 0 0</fdir1>
                <slip1>0</slip1>
                <slip2>0</slip2>
              </ode>
            </friction>
            <bounce>
              <restitution_coefficient>0</restitution_coefficient>
              <threshold>100000</threshold>
            </bounce>
            <contact>
              <ode>
                <soft_cfm>0</soft_cfm>
                <soft_erp>0.2</soft_erp>
                <kp>1e+12</kp>
                <kd>1</kd>
                <max_vel>0</max_vel>
                <min_depth>0.001</min_depth>
              </ode>
            </contact>
          </surface>
          <laser_retro>0</laser_retro>
          <max_contacts>10</max_contacts>
        </collision>
        <visual name='torso_geom_visual'>
          <pose>0 0 0.35 0 -0 0</pose>
          <geometry>
            <box>
              <size>0.1 0.6 0.7</size>
            </box>
          </geometry>
          <cast_shadows>1</cast_shadows>
          <laser_retro>0</laser_retro>
          <transparency>0</transparency>
        </visual>
        <gravity>0</gravity>
        <self_collide>0</self_collide>
        <kinematic>0</kinematic>
        <velocity_decay>
          <linear>0</linear>
          <angular>0</angular>
        </velocity_decay>
      </link>
      <link name='l_shoulder'>
        <pose>0 0.3275 0.9225 0 -0 0</pose>
        <inertial>
          <inertia>
            <ixx>0.01</ixx>
            <ixy>0</ixy>
            <ixz>0</ixz>
            <iyy>0.01</iyy>
            <iyz>0</iyz>
            <izz>0.01</izz>
          </inertia>
          <mass>1</mass>
        </inertial>
        <collision name='l_shoulder_geom'>
          <geometry>
            <sphere>
              <radius>0.055</radius>
            </sphere>
          </geometry>
          <surface>
            <friction>
              <ode>
                <mu>-1</mu>
                <mu2>-1</mu2>
                <fdir1>0 0 0</fdir1>
                <slip1>0</slip1>
                <slip2>0</slip2>
              </ode>
            </friction>
            <bounce>
              <restitution_coefficient>0</restitution_coefficient>
              <threshold>100000</threshold>
            </bounce>
            <contact>
              <ode>
                <soft_cfm>0</soft_cfm>
                <soft_erp>0.2</soft_erp>
                <kp>1e+12</kp>
                <kd>1</kd>
                <max_vel>0</max_vel>
                <min_depth>0.001</min_depth>
              </ode>
            </contact>
          </surface>
          <laser_retro>0</laser_retro>
          <max_contacts>10</max_contacts>
        </collision>
        <visual name='l_shoulder_geom_visual'>
          <geometry>
            <sphere>
              <radius>0.055</radius>
            </sphere>
          </geometry>
          <cast_shadows>1</cast_shadows>
          <laser_retro>0</laser_retro>
          <transparency>0</transparency>
        </visual>
        <gravity>0</gravity>
        <self_collide>0</self_collide>
        <kinematic>0</kinematic>
        <velocity_decay>
          <linear>0</linear>
          <angular>0</angular>
        </velocity_decay>
      </link>
      <link name='l_upper_arm'>
        <pose>0 0.3275 0.9225 0 -0 0</pose>
        <inertial>
          <inertia>
            <ixx>0.02</ixx>
            <ixy>0</ixy>
            <ixz>0</ixz>
            <iyy>0.02</iyy>
            <iyz>0</iyz>
            <izz>0.02</izz>
          </inertia>
          <mass>2</mass>
        </inertial>
        <collision name='l_upper_arm_geom'>
          <pose>0 0 -0.3 0 -0 0</pose>
          <geometry>
            <cylinder>
              <radius>0.055</radius>
              <length>0.6</length>
            </cylinder>
          </geometry>
          <surface>
            <friction>
              <ode>
                <mu>-1</mu>
                <mu2>-1</mu2>
                <fdir1>0 0 0</fdir1>
                <slip1>0</slip1>
                <slip2>0</slip2>
              </ode>
            </friction>
            <bounce>
              <restitution_coefficient>0</restitution_coefficient>
              <threshold>100000</threshold>
            </bounce>
            <contact>
              <ode>
                <soft_cfm>0</soft_cfm>
                <soft_erp>0.2</soft_erp>
                <kp>1e+12</kp>
                <kd>1</kd>
                <max_vel>0</max_vel>
                <min_depth>0.001</min_depth>
              </ode>
            </contact>
          </surface>
          <laser_retro>0</laser_retro>
          <max_contacts>10</max_contacts>
        </collision>
        <visual name='l_upper_arm_geom_visual'>
          <pose>0 0 -0.3 0 -0 0</pose>
          <geometry>
            <cylinder>
              <radius>0.055</radius>
              <length>0.6</length>
            </cylinder>
          </geometry>
          <cast_shadows>1</cast_shadows>
          <laser_retro>0</laser_retro>
          <transparency>0</transparency>
        </visual>
        <gravity>0</gravity>
        <self_collide>0</self_collide>
        <kinematic>0</kinematic>
        <velocity_decay>
          <linear>0</linear>
          <angular>0</angular>
        </velocity_decay>
      </link>
      <link name='l_forearm'>
        <pose>0 0.3275 0.3225 0 -0 0</pose>
        <inertial>
          <inertia>
            <ixx>0.01</ixx>
            <ixy>0</ixy>
            <ixz>0</ixz>
            <iyy>0.01</iyy>
            <iyz>0</iyz>
            <izz>0.01</izz>
          </inertia>
          <mass>1</mass>
        </inertial>
        <collision name='l_forearm_geom'>
          <pose>0 0 -0.225 0 -0 0</pose>
          <geometry>
            <cylinder>
              <radius>0.05</radius>
              <length>0.45</length>
            </cylinder>
          </geometry>
          <surface>
            <friction>
              <ode>
                <mu>-1</mu>
                <mu2>-1</mu2>
                <fdir1>0 0 0</fdir1>
                <slip1>0</slip1>
                <slip2>0</slip2>
              </ode>
            </friction>
            <bounce>
              <restitution_coefficient>0</restitution_coefficient>
              <threshold>100000</threshold>
            </bounce>
            <contact>
              <ode>
                <soft_cfm>0</soft_cfm>
                <soft_erp>0.2</soft_erp>
                <kp>1e+12</kp>
                <kd>1</kd>
                <max_vel>0</max_vel>
                <min_depth>0.001</min_depth>
              </ode>
            </contact>
          </surface>
          <laser_retro>0</laser_retro>
          <max_contacts>10</max_contacts>
        </collision>
        <visual name='l_forearm_geom_visual'>
          <pose>0 0 -0.225 0 -0 0</pose>
          <geometry>
            <cylinder>
              <radius>0.05</radius>
              <length>0.45</length>
            </cylinder>
          </geometry>
          <cast_shadows>1</cast_shadows>
          <laser_retro>0</laser_retro>
          <transparency>0</transparency>
        </visual>
        <gravity>0</gravity>
        <self_collide>0</self_collide>
        <kinematic>0</kinematic>
        <velocity_decay>
          <linear>0</linear>
          <angular>0</angular>
        </velocity_decay>
      </link>
      <link name='l_wrist'>
        <pose>0 0.3275 -0.1425 0 -0 0</pose>
        <inertial>
          <inertia>
            <ixx>0.01</ixx>
            <ixy>0</ixy>
            <ixz>0</ixz>
            <iyy>0.01</iyy>
            <iyz>0</iyz>
            <izz>0.01</izz>
          </inertia>
          <mass>1</mass>
        </inertial>
        <collision name='l_wrist_geom'>
          <geometry>
            <sphere>
              <radius>0.03</radius>
            </sphere>
          </geometry>
          <surface>
            <friction>
              <ode>
                <mu>-1</mu>
                <mu2>-1</mu2>
                <fdir1>0 0 0</fdir1>
                <slip1>0</slip1>
                <slip2>0</slip2>
              </ode>
            </friction>
            <bounce>
              <restitution_coefficient>0</restitution_coefficient>
              <threshold>100000</threshold>
            </bounce>
            <contact>
              <ode>
                <soft_cfm>0</soft_cfm>
                <soft_erp>0.2</soft_erp>
                <kp>1e+12</kp>
                <kd>1</kd>
                <max_vel>0</max_vel>
                <min_depth>0.001</min_depth>
              </ode>
            </contact>
          </surface>
          <laser_retro>0</laser_retro>
          <max_contacts>10</max_contacts>
        </collision>
        <visual name='l_wrist_geom_visual'>
          <geometry>
            <sphere>
              <radius>0.03</radius>
            </sphere>
          </geometry>
          <cast_shadows>1</cast_shadows>
          <laser_retro>0</laser_retro>
          <transparency>0</transparency>
        </visual>
        <gravity>0</gravity>
        <self_collide>0</self_collide>
        <kinematic>0</kinematic>
        <velocity_decay>
          <linear>0</linear>
          <angular>0</angular>
        </velocity_decay>
      </link>
      <link name='l_hand'>
        <pose>0 0.3275 -0.1575 0 -0 0</pose>
        <inertial>
          <inertia>
            <ixx>0.01</ixx>
            <ixy>0</ixy>
            <ixz>0</ixz>
            <iyy>0.01</iyy>
            <iyz>0</iyz>
            <izz>0.01</izz>
          </inertia>
          <mass>1</mass>
        </inertial>
        <collision name='l_hand_geom'>
          <pose>0 0 -0.1 0 -0 0</pose>
          <geometry>
            <box>
              <size>0.03 0.1 0.2</size>
            </box>
          </geometry>
          <surface>
            <friction>
              <ode>
                <mu>-1</mu>
                <mu2>-1</mu2>
                <fdir1>0 0 0</fdir1>
                <slip1>0</slip1>
                <slip2>0</slip2>
              </ode>
            </friction>
            <bounce>
              <restitution_coefficient>0</restitution_coefficient>
              <threshold>100000</threshold>
            </bounce>
            <contact>
              <ode>
                <soft_cfm>0</soft_cfm>
                <soft_erp>0.2</soft_erp>
                <kp>1e+12</kp>
                <kd>1</kd>
                <max_vel>0</max_vel>
                <min_depth>0.001</min_depth>
              </ode>
            </contact>
          </surface>
          <laser_retro>0</laser_retro>
          <max_contacts>10</max_contacts>
        </collision>
        <visual name='l_hand_geom_visual'>
          <pose>0 0 -0.1 0 -0 0</pose>
          <geometry>
            <box>
              <size>0.03 0.1 0.2</size>
            </box>
          </geometry>
          <cast_shadows>1</cast_shadows>
          <laser_retro>0</laser_retro>
          <transparency>0</transparency>
        </visual>
        <gravity>0</gravity>
        <self_collide>0</self_collide>
        <kinematic>0</kinematic>
        <velocity_decay>
          <linear>0</linear>
          <angular>0</angular>
        </velocity_decay>
      </link>
      <link name='neck'>
        <pose>0 0 0.95 0 -0 0</pose>
        <inertial>
          <inertia>
            <ixx>0.01</ixx>
            <ixy>0</ixy>
            <ixz>0</ixz>
            <iyy>0.01</iyy>
            <iyz>0</iyz>
            <izz>0.01</izz>
          </inertia>
          <mass>1</mass>
        </inertial>
        <collision name='neck_geom'>
          <pose>0 0 0.1 0 -0 0</pose>
          <geometry>
            <cylinder>
              <radius>0.075</radius>
              <length>0.2</length>
            </cylinder>
          </geometry>
          <surface>
            <friction>
              <ode>
                <mu>-1</mu>
                <mu2>-1</mu2>
                <fdir1>0 0 0</fdir1>
                <slip1>0</slip1>
                <slip2>0</slip2>
              </ode>
            </friction>
            <bounce>
              <restitution_coefficient>0</restitution_coefficient>
              <threshold>100000</threshold>
            </bounce>
            <contact>
              <ode>
                <soft_cfm>0</soft_cfm>
                <soft_erp>0.2</soft_erp>
                <kp>1e+12</kp>
                <kd>1</kd>
                <max_vel>0</max_vel>
                <min_depth>0.001</min_depth>
              </ode>
            </contact>
          </surface>
          <laser_retro>0</laser_retro>
          <max_contacts>10</max_contacts>
        </collision>
        <visual name='neck_geom_visual'>
          <pose>0 0 0.1 0 -0 0</pose>
          <geometry>
            <cylinder>
              <radius>0.075</radius>
              <length>0.2</length>
            </cylinder>
          </geometry>
          <cast_shadows>1</cast_shadows>
          <laser_retro>0</laser_retro>
          <transparency>0</transparency>
        </visual>
        <gravity>0</gravity>
        <self_collide>0</self_collide>
        <kinematic>0</kinematic>
        <velocity_decay>
          <linear>0</linear>
          <angular>0</angular>
        </velocity_decay>
      </link>
      <link name='head'>
        <pose>0 0 1.225 0 -0 0</pose>
        <inertial>
          <inertia>
            <ixx>0.1</ixx>
            <ixy>0</ixy>
            <ixz>0</ixz>
            <iyy>0.1</iyy>
            <iyz>0</iyz>
            <izz>0.1</izz>
          </inertia>
          <mass>10</mass>
        </inertial>
        <collision name='head_geom'>
          <geometry>
            <sphere>
              <radius>0.15</radius>
            </sphere>
          </geometry>
          <surface>
            <friction>
              <ode>
                <mu>-1</mu>
                <mu2>-1</mu2>
                <fdir1>0 0 0</fdir1>
                <slip1>0</slip1>
                <slip2>0</slip2>
              </ode>
            </friction>
            <bounce>
              <restitution_coefficient>0</restitution_coefficient>
              <threshold>100000</threshold>
            </bounce>
            <contact>
              <ode>
                <soft_cfm>0</soft_cfm>
                <soft_erp>0.2</soft_erp>
                <kp>1e+12</kp>
                <kd>1</kd>
                <max_vel>0</max_vel>
                <min_depth>0.001</min_depth>
              </ode>
            </contact>
          </surface>
          <laser_retro>0</laser_retro>
          <max_contacts>10</max_contacts>
        </collision>
        <visual name='head_geom_visual'>
          <geometry>
            <sphere>
              <radius>0.15</radius>
            </sphere>
          </geometry>
          <cast_shadows>1</cast_shadows>
          <laser_retro>0</laser_retro>
          <transparency>0</transparency>
        </visual>
        <gravity>0</gravity>
        <self_collide>0</self_collide>
        <kinematic>0</kinematic>
        <velocity_decay>
          <linear>0</linear>
          <angular>0</angular>
        </velocity_decay>
      </link>
      <link name='r_shoulder'>
        <pose>0 -0.3275 0.9225 0 -0 0</pose>
        <inertial>
          <inertia>
            <ixx>0.01</ixx>
            <ixy>0</ixy>
            <ixz>0</ixz>
            <iyy>0.01</iyy>
            <iyz>0</iyz>
            <izz>0.01</izz>
          </inertia>
          <mass>1</mass>
        </inertial>
        <collision name='r_shoulder_geom'>
          <geometry>
            <sphere>
              <radius>0.055</radius>
            </sphere>
          </geometry>
          <surface>
            <friction>
              <ode>
                <mu>-1</mu>
                <mu2>-1</mu2>
                <fdir1>0 0 0</fdir1>
                <slip1>0</slip1>
                <slip2>0</slip2>
              </ode>
            </friction>
            <bounce>
              <restitution_coefficient>0</restitution_coefficient>
              <threshold>100000</threshold>
            </bounce>
            <contact>
              <ode>
                <soft_cfm>0</soft_cfm>
                <soft_erp>0.2</soft_erp>
                <kp>1e+12</kp>
                <kd>1</kd>
                <max_vel>0</max_vel>
                <min_depth>0.001</min_depth>
              </ode>
            </contact>
          </surface>
          <laser_retro>0</laser_retro>
          <max_contacts>10</max_contacts>
        </collision>
        <visual name='r_shoulder_geom_visual'>
          <geometry>
            <sphere>
              <radius>0.055</radius>
            </sphere>
          </geometry>
          <cast_shadows>1</cast_shadows>
          <laser_retro>0</laser_retro>
          <transparency>0</transparency>
        </visual>
        <gravity>0</gravity>
        <self_collide>0</self_collide>
        <kinematic>0</kinematic>
        <velocity_decay>
          <linear>0</linear>
          <angular>0</angular>
        </velocity_decay>
      </link>
      <link name='r_upper_arm'>
        <pose>0 -0.3275 0.9225 0 -0 0</pose>
        <inertial>
          <inertia>
            <ixx>0.02</ixx>
            <ixy>0</ixy>
            <ixz>0</ixz>
            <iyy>0.02</iyy>
            <iyz>0</iyz>
            <izz>0.02</izz>
          </inertia>
          <mass>2</mass>
        </inertial>
        <collision name='r_upper_arm_geom'>
          <pose>0 0 -0.3 0 -0 0</pose>
          <geometry>
            <cylinder>
              <radius>0.055</radius>
              <length>0.6</length>
            </cylinder>
          </geometry>
          <surface>
            <friction>
              <ode>
                <mu>-1</mu>
                <mu2>-1</mu2>
                <fdir1>0 0 0</fdir1>
                <slip1>0</slip1>
                <slip2>0</slip2>
              </ode>
            </friction>
            <bounce>
              <restitution_coefficient>0</restitution_coefficient>
              <threshold>100000</threshold>
            </bounce>
            <contact>
              <ode>
                <soft_cfm>0</soft_cfm>
                <soft_erp>0.2</soft_erp>
                <kp>1e+12</kp>
                <kd>1</kd>
                <max_vel>0</max_vel>
                <min_depth>0.001</min_depth>
              </ode>
            </contact>
          </surface>
          <laser_retro>0</laser_retro>
          <max_contacts>10</max_contacts>
        </collision>
        <visual name='r_upper_arm_geom_visual'>
          <pose>0 0 -0.3 0 -0 0</pose>
          <geometry>
            <cylinder>
              <radius>0.055</radius>
              <length>0.6</length>
            </cylinder>
          </geometry>
          <cast_shadows>1</cast_shadows>
          <laser_retro>0</laser_retro>
          <transparency>0</transparency>
        </visual>
        <gravity>0</gravity>
        <self_collide>0</self_collide>
        <kinematic>0</kinematic>
        <velocity_decay>
          <linear>0</linear>
          <angular>0</angular>
        </velocity_decay>
      </link>
      <link name='r_forearm'>
        <pose>0 -0.3275 0.3225 0 -0 0</pose>
        <inertial>
          <inertia>
            <ixx>0.01</ixx>
            <ixy>0</ixy>
            <ixz>0</ixz>
            <iyy>0.01</iyy>
            <iyz>0</iyz>
            <izz>0.01</izz>
          </inertia>
          <mass>1</mass>
        </inertial>
        <collision name='r_forearm_geom'>
          <pose>0 0 -0.225 0 -0 0</pose>
          <geometry>
            <cylinder>
              <radius>0.05</radius>
              <length>0.45</length>
            </cylinder>
          </geometry>
          <surface>
            <friction>
              <ode>
                <mu>-1</mu>
                <mu2>-1</mu2>
                <fdir1>0 0 0</fdir1>
                <slip1>0</slip1>
                <slip2>0</slip2>
              </ode>
            </friction>
            <bounce>
              <restitution_coefficient>0</restitution_coefficient>
              <threshold>100000</threshold>
            </bounce>
            <contact>
              <ode>
                <soft_cfm>0</soft_cfm>
                <soft_erp>0.2</soft_erp>
                <kp>1e+12</kp>
                <kd>1</kd>
                <max_vel>0</max_vel>
                <min_depth>0.001</min_depth>
              </ode>
            </contact>
          </surface>
          <laser_retro>0</laser_retro>
          <max_contacts>10</max_contacts>
        </collision>
        <visual name='r_forearm_geom_visual'>
          <pose>0 0 -0.225 0 -0 0</pose>
          <geometry>
            <cylinder>
              <radius>0.05</radius>
              <length>0.45</length>
            </cylinder>
          </geometry>
          <cast_shadows>1</cast_shadows>
          <laser_retro>0</laser_retro>
          <transparency>0</transparency>
        </visual>
        <gravity>0</gravity>
        <self_collide>0</self_collide>
        <kinematic>0</kinematic>
        <velocity_decay>
          <linear>0</linear>
          <angular>0</angular>
        </velocity_decay>
      </link>
      <link name='r_wrist'>
        <pose>0 -0.3275 -0.1425 0 -0 0</pose>
        <inertial>
          <inertia>
            <ixx>0.01</ixx>
            <ixy>0</ixy>
            <ixz>0</ixz>
            <iyy>0.01</iyy>
            <iyz>0</iyz>
            <izz>0.01</izz>
          </inertia>
          <mass>1</mass>
        </inertial>
        <collision name='r_wrist_geom'>
          <geometry>
            <sphere>
              <radius>0.03</radius>
            </sphere>
          </geometry>
          <surface>
            <friction>
              <ode>
                <mu>-1</mu>
                <mu2>-1</mu2>
                <fdir1>0 0 0</fdir1>
                <slip1>0</slip1>
                <slip2>0</slip2>
              </ode>
            </friction>
            <bounce>
              <restitution_coefficient>0</restitution_coefficient>
              <threshold>100000</threshold>
            </bounce>
            <contact>
              <ode>
                <soft_cfm>0</soft_cfm>
                <soft_erp>0.2</soft_erp>
                <kp>1e+12</kp>
                <kd>1</kd>
                <max_vel>0</max_vel>
                <min_depth>0.001</min_depth>
              </ode>
            </contact>
          </surface>
          <laser_retro>0</laser_retro>
          <max_contacts>10</max_contacts>
        </collision>
        <visual name='r_wrist_geom_visual'>
          <geometry>
            <sphere>
              <radius>0.03</radius>
            </sphere>
          </geometry>
          <cast_shadows>1</cast_shadows>
          <laser_retro>0</laser_retro>
          <transparency>0</transparency>
        </visual>
        <gravity>0</gravity>
        <self_collide>0</self_collide>
        <kinematic>0</kinematic>
        <velocity_decay>
          <linear>0</linear>
          <angular>0</angular>
        </velocity_decay>
      </link>
      <link name='r_hand'>
        <pose>0 -0.3275 -0.1575 0 -0 0</pose>
        <inertial>
          <inertia>
            <ixx>0.01</ixx>
            <ixy>0</ixy>
            <ixz>0</ixz>
            <iyy>0.01</iyy>
            <iyz>0</iyz>
            <izz>0.01</izz>
          </inertia>
          <mass>1</mass>
        </inertial>
        <collision name='r_hand_geom'>
          <pose>0 0 -0.1 0 -0 0</pose>
          <geometry>
            <box>
              <size>0.03 0.1 0.2</size>
            </box>
          </geometry>
          <surface>
            <friction>
              <ode>
                <mu>-1</mu>
                <mu2>-1</mu2>
                <fdir1>0 0 0</fdir1>
                <slip1>0</slip1>
                <slip2>0</slip2>
              </ode>
            </friction>
            <bounce>
              <restitution_coefficient>0</restitution_coefficient>
              <threshold>100000</threshold>
            </bounce>
            <contact>
              <ode>
                <soft_cfm>0</soft_cfm>
                <soft_erp>0.2</soft_erp>
                <kp>1e+12</kp>
                <kd>1</kd>
                <max_vel>0</max_vel>
                <min_depth>0.001</min_depth>
              </ode>
            </contact>
          </surface>
          <laser_retro>0</laser_retro>
          <max_contacts>10</max_contacts>
        </collision>
        <visual name='r_hand_geom_visual'>
          <pose>0 0 -0.1 0 -0 0</pose>
          <geometry>
            <box>
              <size>0.03 0.1 0.2</size>
            </box>
          </geometry>
          <cast_shadows>1</cast_shadows>
          <laser_retro>0</laser_retro>
          <transparency>0</transparency>
        </visual>
        <gravity>0</gravity>
        <self_collide>0</self_collide>
        <kinematic>0</kinematic>
        <velocity_decay>
          <linear>0</linear>
          <angular>0</angular>
        </velocity_decay>
      </link>
      <joint name='l_thigh_pan_joint' type='revolute'>
        <parent>hip</parent>
        <child>l_thigh_pan</child>
        <axis>
          <dynamics>
            <damping>0</damping>
            <friction>0</friction>
          </dynamics>
          <limit>
            <lower>-1.5708</lower>
            <upper>1.5708</upper>
            <effort>0</effort>
            <velocity>0</velocity>
          </limit>
          <xyz>0 0 1</xyz>
        </axis>
      </joint>
      <joint name='l_thigh_lift_joint' type='revolute'>
        <parent>l_thigh_pan</parent>
        <child>l_thigh_lift</child>
        <axis>
          <dynamics>
            <damping>0</damping>
            <friction>0</friction>
          </dynamics>
          <limit>
            <lower>-1.5708</lower>
            <upper>1.5708</upper>
            <effort>0</effort>
            <velocity>0</velocity>
          </limit>
          <xyz>0 1 0</xyz>
        </axis>
      </joint>
      <joint name='l_calf_joint' type='revolute'>
        <parent>l_thigh_lift</parent>
        <child>l_calf</child>
        <axis>
          <dynamics>
            <damping>0</damping>
            <friction>0</friction>
          </dynamics>
          <limit>
            <lower>-1.5708</lower>
            <upper>1.5708</upper>
            <effort>0</effort>
            <velocity>0</velocity>
          </limit>
          <xyz>0 1 0</xyz>
        </axis>
      </joint>
      <joint name='l_ankle_joint' type='revolute'>
        <parent>l_calf</parent>
        <child>l_ankle</child>
        <axis>
          <dynamics>
            <damping>0</damping>
            <friction>0</friction>
          </dynamics>
          <limit>
            <lower>-1.5708</lower>
            <upper>1.5708</upper>
            <effort>0</effort>
            <velocity>0</velocity>
          </limit>
          <xyz>0 1 0</xyz>
        </axis>
      </joint>
      <joint name='l_foot_joint' type='revolute'>
        <parent>l_ankle</parent>
        <child>l_foot</child>
        <axis>
          <dynamics>
            <damping>0</damping>
            <friction>0</friction>
          </dynamics>
          <limit>
            <lower>-1.5708</lower>
            <upper>1.5708</upper>
            <effort>0</effort>
            <velocity>0</velocity>
          </limit>
          <xyz>1 0 0</xyz>
        </axis>
      </joint>
      <joint name='r_thigh_pan_joint' type='revolute'>
        <parent>hip</parent>
        <child>r_thigh_pan</child>
        <axis>
          <dynamics>
            <damping>0</damping>
            <friction>0</friction>
          </dynamics>
          <limit>
            <lower>-1.5708</lower>
            <upper>1.5708</upper>
            <effort>0</effort>
            <velocity>0</velocity>
          </limit>
          <xyz>0 0 1</xyz>
        </axis>
      </joint>
      <joint name='r_thigh_lift_joint' type='revolute'>
        <parent>r_thigh_pan</parent>
        <child>r_thigh_lift</child>
        <axis>
          <dynamics>
            <damping>0</damping>
            <friction>0</friction>
          </dynamics>
          <limit>
            <lower>-1.5708</lower>
            <upper>1.5708</upper>
            <effort>0</effort>
            <velocity>0</velocity>
          </limit>
          <xyz>0 1 0</xyz>
        </axis>
      </joint>
      <joint name='r_calf_joint' type='revolute'>
        <parent>r_thigh_lift</parent>
        <child>r_calf</child>
        <axis>
          <dynamics>
            <damping>0</damping>
            <friction>0</friction>
          </dynamics>
          <limit>
            <lower>-1.5708</lower>
            <upper>1.5708</upper>
            <effort>0</effort>
            <velocity>0</velocity>
          </limit>
          <xyz>0 1 0</xyz>
        </axis>
      </joint>
      <joint name='r_ankle_joint' type='revolute'>
        <parent>r_calf</parent>
        <child>r_ankle</child>
        <axis>
          <dynamics>
            <damping>0</damping>
            <friction>0</friction>
          </dynamics>
          <limit>
            <lower>-1.5708</lower>
            <upper>1.5708</upper>
            <effort>0</effort>
            <velocity>0</velocity>
          </limit>
          <xyz>0 1 0</xyz>
        </axis>
      </joint>
      <joint name='r_foot_joint' type='revolute'>
        <parent>r_ankle</parent>
        <child>r_foot</child>
        <axis>
          <dynamics>
            <damping>0</damping>
            <friction>0</friction>
          </dynamics>
          <limit>
            <lower>-1.5708</lower>
            <upper>1.5708</upper>
            <effort>0</effort>
            <velocity>0</velocity>
          </limit>
          <xyz>1 0 0</xyz>
        </axis>
      </joint>
      <joint name='torso_joint' type='revolute'>
        <parent>hip</parent>
        <child>torso</child>
        <axis>
          <dynamics>
            <damping>0</damping>
            <friction>0</friction>
          </dynamics>
          <limit>
            <lower>-1.5708</lower>
            <upper>1.5708</upper>
            <effort>0</effort>
            <velocity>0</velocity>
          </limit>
          <xyz>0 1 0</xyz>
        </axis>
      </joint>
      <joint name='l_shoulder_joint' type='revolute'>
        <parent>torso</parent>
        <child>l_shoulder</child>
        <axis>
          <dynamics>
            <damping>0</damping>
            <friction>0</friction>
          </dynamics>
          <limit>
            <lower>-1.5708</lower>
            <upper>1.5708</upper>
            <effort>0</effort>
            <velocity>0</velocity>
          </limit>
          <xyz>1 0 0</xyz>
        </axis>
      </joint>
      <joint name='l_upper_arm_joint' type='revolute'>
        <parent>l_shoulder</parent>
        <child>l_upper_arm</child>
        <axis>
          <dynamics>
            <damping>0</damping>
            <friction>0</friction>
          </dynamics>
          <limit>
            <lower>-1.5708</lower>
            <upper>1.5708</upper>
            <effort>0</effort>
            <velocity>0</velocity>
          </limit>
          <xyz>0 1 0</xyz>
        </axis>
      </joint>
      <joint name='l_forearm_joint' type='revolute'>
        <parent>l_upper_arm</parent>
        <child>l_forearm</child>
        <axis>
          <dynamics>
            <damping>0</damping>
            <friction>0</friction>
          </dynamics>
          <limit>
            <lower>-1.5708</lower>
            <upper>1.5708</upper>
            <effort>0</effort>
            <velocity>0</velocity>
          </limit>
          <xyz>0 1 0</xyz>
        </axis>
      </joint>
      <joint name='l_wrist_joint' type='revolute'>
        <parent>l_forearm</parent>
        <child>l_wrist</child>
        <axis>
          <dynamics>
            <damping>0</damping>
            <friction>0</friction>
          </dynamics>
          <limit>
            <lower>-1.5708</lower>
            <upper>1.5708</upper>
            <effort>0</effort>
            <velocity>0</velocity>
          </limit>
          <xyz>0 1 0</xyz>
        </axis>
      </joint>
      <joint name='l_hand_joint' type='revolute'>
        <parent>l_wrist</parent>
        <child>l_hand</child>
        <axis>
          <dynamics>
            <damping>0</damping>
            <friction>0</friction>
          </dynamics>
          <limit>
            <lower>-1.5708</lower>
            <upper>1.5708</upper>
            <effort>0</effort>
            <velocity>0</velocity>
          </limit>
          <xyz>0 1 0</xyz>
        </axis>
      </joint>
      <joint name='neck_joint' type='revolute'>
        <parent>torso</parent>
        <child>neck</child>
        <axis>
          <dynamics>
            <damping>0</damping>
            <friction>0</friction>
          </dynamics>
          <limit>
            <lower>-1.5708</lower>
            <upper>1.5708</upper>
            <effort>0</effort>
            <velocity>0</velocity>
          </limit>
          <xyz>0 0 1</xyz>
        </axis>
      </joint>
      <joint name='head_joint' type='revolute'>
        <parent>neck</parent>
        <child>head</child>
        <axis>
          <dynamics>
            <damping>0</damping>
            <friction>0</friction>
          </dynamics>
          <limit>
            <lower>-1.5708</lower>
            <upper>1.5708</upper>
            <effort>0</effort>
            <velocity>0</velocity>
          </limit>
          <xyz>0 1 0</xyz>
        </axis>
      </joint>
      <joint name='r_shoulder_joint' type='revolute'>
        <parent>torso</parent>
        <child>r_shoulder</child>
        <axis>
          <dynamics>
            <damping>0</damping>
            <friction>0</friction>
          </dynamics>
          <limit>
            <lower>-1.5708</lower>
            <upper>1.5708</upper>
            <effort>0</effort>
            <velocity>0</velocity>
          </limit>
          <xyz>1 0 0</xyz>
        </axis>
      </joint>
      <joint name='r_upper_arm_joint' type='revolute'>
        <parent>r_shoulder</parent>
        <child>r_upper_arm</child>
        <axis>
          <dynamics>
            <damping>0</damping>
            <friction>0</friction>
          </dynamics>
          <limit>
            <lower>-1.5708</lower>
            <upper>1.5708</upper>
            <effort>0</effort>
            <velocity>0</velocity>
          </limit>
          <xyz>0 1 0</xyz>
        </axis>
      </joint>
      <joint name='r_forearm_joint' type='revolute'>
        <parent>r_upper_arm</parent>
        <child>r_forearm</child>
        <axis>
          <dynamics>
            <damping>0</damping>
            <friction>0</friction>
          </dynamics>
          <limit>
            <lower>-1.5708</lower>
            <upper>1.5708</upper>
            <effort>0</effort>
            <velocity>0</velocity>
          </limit>
          <xyz>0 1 0</xyz>
        </axis>
      </joint>
      <joint name='r_wrist_joint' type='revolute'>
        <parent>r_forearm</parent>
        <child>r_wrist</child>
        <axis>
          <dynamics>
            <damping>0</damping>
            <friction>0</friction>
          </dynamics>
          <limit>
            <lower>-1.5708</lower>
            <upper>1.5708</upper>
            <effort>0</effort>
            <velocity>0</velocity>
          </limit>
          <xyz>0 1 0</xyz>
        </axis>
      </joint>
      <joint name='r_hand_joint' type='revolute'>
        <parent>r_wrist</parent>
        <child>r_hand</child>
        <axis>
          <dynamics>
            <damping>0</damping>
            <friction>0</friction>
          </dynamics>
          <limit>
            <lower>-1.5708</lower>
            <upper>1.5708</upper>
            <effort>0</effort>
            <velocity>0</velocity>
          </limit>
          <xyz>0 1 0</xyz>
        </axis>
      </joint>
      <static>0</static>
    </model>
    <model name='Speed limit'>
      <static>1</static>
      <link name='link'>
        <collision name='collision'>
          <geometry>
            <mesh>
              <scale>10 10 10</scale>
              <uri>model://speed_limit_sign/meshes/speed_limit_sign.dae</uri>
            </mesh>
          </geometry>
          <max_contacts>10</max_contacts>
          <surface>
            <bounce/>
            <friction>
              <ode/>
            </friction>
            <contact>
              <ode/>
            </contact>
          </surface>
        </collision>
        <visual name='visual'>
          <geometry>
            <mesh>
              <scale>10 10 10</scale>
              <uri>model://speed_limit_sign/meshes/speed_limit_sign.dae</uri>
            </mesh>
          </geometry>
        </visual>
        <velocity_decay>
          <linear>0</linear>
          <angular>0</angular>
        </velocity_decay>
        <self_collide>0</self_collide>
        <kinematic>0</kinematic>
        <gravity>1</gravity>
      </link>
      <pose>-3 -9 0 0 -0 0</pose>
    </model>
    <model name='Stop Sign'>
      <link name='link'>
        <collision name='collision'>
          <geometry>
            <mesh>
              <uri>model://stop_sign/meshes/stop_sign.dae</uri>
            </mesh>
          </geometry>
          <max_contacts>10</max_contacts>
          <surface>
            <bounce/>
            <friction>
              <ode/>
            </friction>
            <contact>
              <ode/>
            </contact>
          </surface>
        </collision>
        <visual name='visual'>
          <geometry>
            <mesh>
              <uri>model://stop_sign/meshes/stop_sign.dae</uri>
            </mesh>
          </geometry>
          <material>
            <script>
              <uri>model://stop_sign/materials/scripts</uri>
              <uri>model://stop_sign/materials/textures</uri>
              <name>StopSign/Diffuse</name>
            </script>
          </material>
        </visual>
        <velocity_decay>
          <linear>0</linear>
          <angular>0</angular>
        </velocity_decay>
        <self_collide>0</self_collide>
        <inertial>
          <inertia>
            <ixx>1</ixx>
            <ixy>0</ixy>
            <ixz>0</ixz>
            <iyy>1</iyy>
            <iyz>0</iyz>
            <izz>1</izz>
          </inertia>
          <mass>1</mass>
        </inertial>
        <kinematic>0</kinematic>
        <gravity>1</gravity>
      </link>
      <pose>2 4 0 0 -0 0</pose>
      <static>0</static>
    </model>
  </world>
</sdf>
