<sdf version='1.4'>
  <world name='default'>
    <light name='sun' type='directional'>
      <cast_shadows>1</cast_shadows>
      <pose>0 0 10 0 -0 0</pose>
      <diffuse>0.8 0.8 0.8 1</diffuse>
      <specular>0.2 0.2 0.2 1</specular>
      <attenuation>
        <range>1000</range>
        <constant>0.9</constant>
        <linear>0.01</linear>
        <quadratic>0.001</quadratic>
      </attenuation>
      <direction>-0.5 0.1 -0.9</direction>
    </light>
    <model name='ground_plane'>
      <static>1</static>
      <link name='link'>
        <collision name='collision'>
          <geometry>
            <plane>
              <normal>0 0 1</normal>
              <size>100 100</size>
            </plane>
          </geometry>
          <surface>
            <friction>
              <ode>
                <mu>100</mu>
                <mu2>50</mu2>
              </ode>
            </friction>
            <bounce/>
            <contact>
              <ode/>
            </contact>
          </surface>
          <max_contacts>10</max_contacts>
        </collision>
        <visual name='visual'>
          <cast_shadows>0</cast_shadows>
          <geometry>
            <plane>
              <normal>0 0 1</normal>
              <size>100 100</size>
            </plane>
          </geometry>
          <material>
            <script>
              <uri>file://media/materials/scripts/gazebo.material</uri>
              <name>Gazebo/Grey</name>
            </script>
          </material>
        </visual>
        <velocity_decay>
          <linear>0</linear>
          <angular>0</angular>
        </velocity_decay>
        <self_collide>0</self_collide>
        <kinematic>0</kinematic>
        <gravity>1</gravity>
      </link>
    </model>
    <physics type='ode'>
      <max_step_size>0.001</max_step_size>
      <real_time_factor>1</real_time_factor>
      <real_time_update_rate>1000</real_time_update_rate>
      <gravity>0 0 -9.8</gravity>
    </physics>
    <scene>
      <ambient>0.4 0.4 0.4 1</ambient>
      <background>0.7 0.7 0.7 1</background>
      <shadows>1</shadows>
    </scene>
    <spherical_coordinates>
      <surface_model>EARTH_WGS84</surface_model>
      <latitude_deg>0</latitude_deg>
      <longitude_deg>0</longitude_deg>
      <elevation>0</elevation>
      <heading_deg>0</heading_deg>
    </spherical_coordinates>
    <model name='Gas Station'>
      <static>1</static>
      <link name='link'>
        <pose>0 0 0 0 -0 0</pose>
        <collision name='collision'>
          <geometry>
            <mesh>
              <uri>model://gas_station/meshes/gas_station.dae</uri>
            </mesh>
          </geometry>
          <max_contacts>10</max_contacts>
          <surface>
            <bounce/>
            <friction>
              <ode/>
            </friction>
            <contact>
              <ode/>
            </contact>
          </surface>
        </collision>
        <visual name='visual'>
          <geometry>
            <mesh>
              <uri>model://gas_station/meshes/gas_station.dae</uri>
            </mesh>
          </geometry>
          <material>
            <script>
              <uri>model://gas_station/materials/scripts</uri>
              <uri>model://gas_station/materials/textures</uri>
              <name>GasStation/Diffuse</name>
            </script>
            <shader type='normal_map_object_space'>
              <normal_map>GasStation_Normal.png</normal_map>
            </shader>
          </material>
        </visual>
        <velocity_decay>
          <linear>0</linear>
          <angular>0</angular>
        </velocity_decay>
        <self_collide>0</self_collide>
        <kinematic>0</kinematic>
        <gravity>1</gravity>
      </link>
      <pose>-6 10.4275 0 0 -0 0</pose>
    </model>
    <state world_name='default'>
      <sim_time>348 93000000</sim_time>
      <real_time>84 26605000</real_time>
      <wall_time>1468272324 184299363</wall_time>
      <model name='Gas Station'>
        <pose>-6 10.4275 0 0 -0 0</pose>
        <link name='link'>
          <pose>-6 10.4275 0 0 -0 0</pose>
          <velocity>0 0 0 0 -0 0</velocity>
          <acceleration>0 0 0 0 -0 0</acceleration>
          <wrench>0 0 0 0 -0 0</wrench>
        </link>
      </model>
      <model name='Speed limit'>
        <pose>-2 -9 0 0 0 -1.57278</pose>
        <link name='link'>
          <pose>-2 -9 0 0 0 -1.57278</pose>
          <velocity>0 0 0 0 -0 0</velocity>
          <acceleration>0 0 0 0 -0 0</acceleration>
          <wrench>0 0 0 0 -0 0</wrench>
        </link>
      </model>
      <model name='Stop Sign'>
        <pose>3.52624 4 1e-06 -1.3e-05 3.6e-05 0</pose>
        <link name='link'>
          <pose>3.52624 4 1e-06 -1.3e-05 3.6e-05 0</pose>
          <velocity>0 0 0 0 -0 0</velocity>
          <acceleration>-0 -0 -0.010607 -0.107938 -0.303544 0</acceleration>
          <wrench>-0 -0 -0.010607 0 -0 0</wrench>
        </link>
      </model>
      <model name='ground_plane'>
        <pose>0 0 0 0 -0 0</pose>
        <link name='link'>
          <pose>0 0 0 0 -0 0</pose>
          <velocity>0 0 0 0 -0 0</velocity>
          <acceleration>0 0 0 0 -0 0</acceleration>
          <wrench>0 0 0 0 -0 0</wrench>
        </link>
      </model>
      <model name='polaris_ranger_ev'>
        <pose>-5.98832 2.55715 0.000371 0 2.4e-05 1e-05</pose>
        <link name='FNR_switch'>
          <pose>-5.42829 2.53716 1.08036 0 0.222675 1e-05</pose>
          <velocity>0.00074 2.3e-05 -0.005896 -2.7e-05 -0.00173 -1.1e-05</velocity>
          <acceleration>0.000228 -1e-06 2e-06 1e-06 -0 0</acceleration>
          <wrench>2.3e-05 -0 0 0 -0 0</wrench>
        </link>
        <link name='brake_pedal'>
          <pose>-5.30647 2.82716 0.55525 -1e-06 2.5e-05 1e-05</pose>
          <velocity>0.001687 9e-06 -0.005689 -6e-06 -0.00181 -2.3e-05</velocity>
          <acceleration>0.000231 -0 6e-06 0 -0 0</acceleration>
          <wrench>2.3e-05 -0 1e-06 0 -0 0</wrench>
        </link>
        <link name='chassis'>
          <pose>-5.98832 2.55715 0.000371 0 2.4e-05 1e-05</pose>
          <velocity>0.002648 -0 -0.006901 -2.7e-05 -0.001757 -1.1e-05</velocity>
          <acceleration>0.000229 -0 1e-06 0 -1e-06 0</acceleration>
          <wrench>0.164862 -7.3e-05 0.000873 0 -0 0</wrench>
        </link>
        <link name='front_left_wheel'>
          <pose>-4.95819 3.15716 0.320396 -1.51998 0.036444 0.000557</pose>
          <velocity>0.002109 0.000131 -0.00861 0.000957 0.006609 0.000421</velocity>
          <acceleration>0.000229 -0 4e-06 1.29247e-26 3e-05 3e-06</acceleration>
          <wrench>0.00275 -4e-06 4.3e-05 0 -0 0</wrench>
        </link>
        <link name='front_left_wheel_steering_block'>
          <pose>-4.95831 3.05716 0.32041 1.5708 2.4e-05 -0.001264</pose>
          <velocity>0.002113 0.000127 -0.009599 -3.2e-05 -0.001752 -4e-06</velocity>
          <acceleration>0.000229 -0 4e-06 1e-06 -1e-06 -1e-06</acceleration>
          <wrench>0.000229 -0 4e-06 0 -0 0</wrench>
        </link>
        <link name='front_right_wheel'>
          <pose>-4.95823 1.95716 0.320396 1.51998 0.036472 -0.001079</pose>
          <velocity>0.002097 -0.000128 -0.008575 -0.000962 0.006578 -0.000442</velocity>
          <acceleration>0.000229 -0 4e-06 -1.29247e-26 3e-05 -3e-06</acceleration>
          <wrench>0.002749 -1e-06 5.1e-05 0 -0 0</wrench>
        </link>
        <link name='front_right_wheel_steering_block'>
          <pose>-4.95831 2.05716 0.32041 1.5708 2.4e-05 0.000744</pose>
          <velocity>0.002102 -0.000124 -0.009567 3e-06 -0.001762 -1.8e-05</velocity>
          <acceleration>0.000229 -0 5e-06 1e-06 -1e-06 1e-06</acceleration>
          <wrench>0.000229 -0 5e-06 0 -0 0</wrench>
        </link>
        <link name='gas_pedal'>
          <pose>-5.30875 2.65716 0.530799 0 2.5e-05 1e-05</pose>
          <velocity>0.001733 7e-06 -0.005703 -2.2e-05 -0.001796 -1.6e-05</velocity>
          <acceleration>0.000233 -0 7e-06 0 -0 0</acceleration>
          <wrench>2.3e-05 -0 1e-06 0 -0 0</wrench>
        </link>
        <link name='hand_brake'>
          <pose>-5.45829 2.62716 1.05036 0 -0.031528 1e-05</pose>
          <velocity>0.000794 2.2e-05 -0.005952 -2.7e-05 -0.00173 -1.1e-05</velocity>
          <acceleration>0.000228 -1e-06 2e-06 0 -0 0</acceleration>
          <wrench>0.000114 -0 1e-06 0 -0 0</wrench>
        </link>
        <link name='rear_left_wheel'>
          <pose>-6.83831 3.15714 0.320392 -1.51997 0.036437 0.001831</pose>
          <velocity>0.002097 0.000163 -0.008417 0.000804 0.006566 0.000408</velocity>
          <acceleration>0.000229 -0 0 1.29247e-26 3e-05 3e-06</acceleration>
          <wrench>0.002749 -1e-06 4e-06 0 -0 0</wrench>
        </link>
        <link name='rear_right_wheel'>
          <pose>-6.8383 1.95714 0.320392 1.51997 0.036479 -0.001814</pose>
          <velocity>0.002085 -0.000134 -0.008359 -0.000892 0.006535 -0.000428</velocity>
          <acceleration>0.000229 -0 -0 -1.29247e-26 3e-05 -3e-06</acceleration>
          <wrench>0.002749 -1e-06 -5e-06 0 -0 0</wrench>
        </link>
        <link name='steering_wheel'>
          <pose>-5.64829 2.85716 1.29036 -0.000306 -0.869975 0.00041</pose>
          <velocity>0.000371 3.1e-05 -0.006295 -2.7e-05 -0.001772 -1.1e-05</velocity>
          <acceleration>0.000228 -1e-06 2e-06 0 -0 0</acceleration>
          <wrench>0.000228 -1e-06 2e-06 0 -0 0</wrench>
        </link>
      </model>
      <model name='ragdoll'>
        <pose>-1.99978 -8.00002 1.4 1.6e-05 -0.001313 -0.005527</pose>
        <link name='head'>
          <pose>-2.0008 -8.00003 2.625 2.8e-05 -0.000749 -0.023302</pose>
          <velocity>-0 -1.1e-05 -5.4e-05 -6.4e-05 6e-06 -1e-06</velocity>
          <acceleration>-0.00016 -0.019704 -0.059941 -0.000193 5.3e-05 -1.2e-05</acceleration>
          <wrench>-0.0016 -0.197041 -0.599407 0 -0 0</wrench>
        </link>
        <link name='hip'>
          <pose>-1.99978 -8.00002 1.4 1.6e-05 -0.001313 -0.005527</pose>
          <velocity>0 2.6e-05 -5.8e-05 0.000103 1e-06 0.000141</velocity>
          <acceleration>-0.001886 0.012506 -0.063992 0.000807 0.000111 -2.9e-05</acceleration>
          <wrench>-0.018862 0.125058 -0.639917 0 -0 0</wrench>
        </link>
        <link name='l_ankle'>
          <pose>-1.99375 -7.78009 0.075 3.8e-05 4e-06 -0.023134</pose>
          <velocity>-1.5e-05 -5.5e-05 -8e-06 -9.5e-05 -0.000255 -4.3e-05</velocity>
          <acceleration>-0.012261 -0.104738 -0.021932 -0.001082 -0.001952 -0.000305</acceleration>
          <wrench>-0.012261 -0.104738 -0.021932 0 -0 0</wrench>
        </link>
        <link name='l_calf'>
          <pose>-1.9905 -7.78019 0.699958 3.8e-05 0.005203 -0.023134</pose>
          <velocity>3.3e-05 -7e-06 -1.9e-05 -8.7e-05 8.3e-05 -5.2e-05</velocity>
          <acceleration>-0.003114 -0.042823 -0.030601 -0.001049 0.000198 -0.000449</acceleration>
          <wrench>-0.006229 -0.085646 -0.061202 0 -0 0</wrench>
        </link>
        <link name='l_foot'>
          <pose>-1.99375 -7.78009 0.05 1e-06 6e-06 -0.023134</pose>
          <velocity>-8e-06 -6.1e-05 8e-06 0.00122 -0.000154 -1e-06</velocity>
          <acceleration>-0.006455 -0.106708 0.001224 0.021353 -0.00129 -6e-06</acceleration>
          <wrench>-0.006455 -0.106708 0.001224 0 -0 0</wrench>
        </link>
        <link name='l_forearm'>
          <pose>-1.99279 -7.67256 1.72247 1.9e-05 -0.001367 -0.005527</pose>
          <velocity>-3e-06 -6e-06 -4.5e-05 1.3e-05 -7e-06 0.000142</velocity>
          <acceleration>-0.001187 -0.007025 -0.052309 0.00017 -2.1e-05 -2.6e-05</acceleration>
          <wrench>-0.001187 -0.007025 -0.052309 0 -0 0</wrench>
        </link>
        <link name='l_hand'>
          <pose>-1.99214 -7.67256 1.24246 1.9e-05 -0.000762 -0.005527</pose>
          <velocity>1e-06 1e-06 -4.5e-05 1.3e-05 -3.5e-05 0.000142</velocity>
          <acceleration>0.000678 0.001603 -0.05214 0.000169 -0.000411 -2.6e-05</acceleration>
          <wrench>0.000678 0.001603 -0.05214 0 -0 0</wrench>
        </link>
        <link name='l_shoulder'>
          <pose>-1.99877 -7.67254 2.3225 1.9e-05 -0.000699 -0.005527</pose>
          <velocity>-4.6e-05 -1.6e-05 -4.5e-05 1.5e-05 -1e-06 0.000142</velocity>
          <acceleration>0.000941 -0.018514 -0.052599 0.000183 -1.1e-05 -2.6e-05</acceleration>
          <wrench>0.000941 -0.018514 -0.052599 0 -0 0</wrench>
        </link>
        <link name='l_thigh_lift'>
          <pose>-1.99857 -7.78003 1.4 3.8e-05 -0.011524 -0.023135</pose>
          <velocity>-3.1e-05 2.4e-05 -2.3e-05 -6.6e-05 -9.2e-05 -5.8e-05</velocity>
          <acceleration>-0.001302 0.010245 -0.034194 -0.000931 2.6e-05 -0.000529</acceleration>
          <wrench>-0.006511 0.051225 -0.17097 0 -0 0</wrench>
        </link>
        <link name='l_thigh_pan'>
          <pose>-1.99857 -7.78003 1.4 3.8e-05 -0.001312 -0.023134</pose>
          <velocity>-3.1e-05 2.4e-05 -2.1e-05 -8.4e-05 6e-06 -5.9e-05</velocity>
          <acceleration>-0.001282 0.009889 -0.033213 -0.001143 0.000157 -0.000552</acceleration>
          <wrench>-0.001282 0.009889 -0.033213 0 -0 0</wrench>
        </link>
        <link name='l_upper_arm'>
          <pose>-1.99877 -7.67254 2.3225 1.9e-05 -0.009978 -0.005527</pose>
          <velocity>-4.6e-05 -1.6e-05 -4.5e-05 1.5e-05 -7.2e-05 0.000142</velocity>
          <acceleration>0.000946 -0.018683 -0.05267 0.000186 3.6e-05 -2.6e-05</acceleration>
          <wrench>0.001893 -0.037366 -0.10534 0 -0 0</wrench>
        </link>
        <link name='l_wrist'>
          <pose>-1.99215 -7.67256 1.25746 1.9e-05 -0.000768 -0.005527</pose>
          <velocity>0 1e-06 -4.5e-05 1.3e-05 -3.4e-05 0.000142</velocity>
          <acceleration>7.4e-05 0.001337 -0.051987 0.000167 -0.000399 -2.6e-05</acceleration>
          <wrench>7.4e-05 0.001337 -0.051987 0 -0 0</wrench>
        </link>
        <link name='neck'>
          <pose>-2.0006 -8.00002 2.35 2.8e-05 -0.000699 -0.023302</pose>
          <velocity>-0 -2e-05 -5.3e-05 -6.5e-05 -0 -1e-06</velocity>
          <acceleration>4.3e-05 -0.021204 -0.058943 -0.000189 -9e-06 -1.2e-05</acceleration>
          <wrench>4.3e-05 -0.021204 -0.058943 0 -0 0</wrench>
        </link>
        <link name='r_ankle'>
          <pose>-2.00403 -8.2199 0.075 3.9e-05 2.1e-05 -0.023464</pose>
          <velocity>-6.4e-05 4.5e-05 -0.00014 -1.7e-05 -0.000613 -0.000263</velocity>
          <acceleration>-0.0537 -0.017476 -0.140203 -0.000316 -0.004759 -0.00237</acceleration>
          <wrench>-0.0537 -0.017476 -0.140203 0 -0 0</wrench>
        </link>
        <link name='r_calf'>
          <pose>-2.00828 -8.21982 0.699958 3.9e-05 -0.006796 -0.023465</pose>
          <velocity>-3.5e-05 4.4e-05 -0.000115 -1e-06 5.8e-05 -0.000271</velocity>
          <acceleration>0.021424 -0.00311 -0.115979 -0.000211 0.001325 -0.002586</acceleration>
          <wrench>0.042848 -0.006219 -0.231959 0 -0 0</wrench>
        </link>
        <link name='r_foot'>
          <pose>-2.00403 -8.2199 0.05 1.05879e-22 2.3e-05 -0.023464</pose>
          <velocity>-4.7e-05 4.2e-05 -0.000183 0.000104 -0.00094 -0.000235</velocity>
          <acceleration>-0.041155 -0.034156 -0.102745 0.01162 -0.008203 -0.002345</acceleration>
          <wrench>-0.041155 -0.034156 -0.102745 0 -0 0</wrench>
        </link>
        <link name='r_forearm'>
          <pose>-2.00746 -8.32743 1.72246 0.000116 -0.000134 -0.005527</pose>
          <velocity>4e-06 -1.2e-05 -6.9e-05 3.1e-05 8e-06 0.000142</velocity>
          <acceleration>0.001317 -0.010096 -0.070651 0.000274 3.3e-05 -2.7e-05</acceleration>
          <wrench>0.001317 -0.010096 -0.070651 0 -0 0</wrench>
        </link>
        <link name='r_hand'>
          <pose>-2.00739 -8.32738 1.24245 0.000116 -0.00073 -0.005527</pose>
          <velocity>-1e-06 3e-06 -6.6e-05 3e-05 4.9e-05 0.000142</velocity>
          <acceleration>-0.000865 0.002278 -0.068575 0.000249 0.000505 -2.6e-05</acceleration>
          <wrench>-0.000865 0.002278 -0.068575 0 -0 0</wrench>
        </link>
        <link name='r_shoulder'>
          <pose>-2.00239 -8.32753 2.32249 0.000116 -0.000699 -0.005527</pose>
          <velocity>4.6e-05 -3.1e-05 -7.2e-05 3.1e-05 -0 0.000142</velocity>
          <acceleration>-0.000883 -0.027512 -0.073284 0.000265 -1e-05 -2.8e-05</acceleration>
          <wrench>-0.000883 -0.027512 -0.073284 0 -0 0</wrench>
        </link>
        <link name='r_thigh_lift'>
          <pose>-2.001 -8.22002 1.4 3.9e-05 0.010397 -0.023464</pose>
          <velocity>3.1e-05 2.5e-05 -0.000104 1.2e-05 9.4e-05 -0.000275</velocity>
          <acceleration>-0.002559 0.011076 -0.105301 -0.000296 -0.000354 -0.002698</acceleration>
          <wrench>-0.012793 0.05538 -0.526503 0 -0 0</wrench>
        </link>
        <link name='r_thigh_pan'>
          <pose>-2.001 -8.22002 1.4 3.9e-05 -0.001312 -0.023464</pose>
          <velocity>3.1e-05 2.5e-05 -0.000107 -1e-06 3e-06 -0.000276</velocity>
          <acceleration>-0.002536 0.010775 -0.107853 -0.000431 0.000136 -0.002738</acceleration>
          <wrench>-0.002536 0.010775 -0.107853 0 -0 0</wrench>
        </link>
        <link name='r_upper_arm'>
          <pose>-2.00239 -8.32753 2.3225 0.000116 0.008442 -0.005526</pose>
          <velocity>4.6e-05 -3e-05 -6.9e-05 3.1e-05 7.1e-05 0.000142</velocity>
          <acceleration>-0.000873 -0.026837 -0.071352 0.000264 -3.7e-05 -2.7e-05</acceleration>
          <wrench>-0.001745 -0.053674 -0.142705 0 -0 0</wrench>
        </link>
        <link name='r_wrist'>
          <pose>-2.00739 -8.32738 1.25745 0.000116 -0.000724 -0.005527</pose>
          <velocity>-0 2e-06 -6.7e-05 3e-05 4.8e-05 0.000142</velocity>
          <acceleration>-0.000127 0.001933 -0.069322 0.000253 0.000498 -2.6e-05</acceleration>
          <wrench>-0.000127 0.001933 -0.069322 0 -0 0</wrench>
        </link>
        <link name='torso'>
          <pose>-2.00011 -8.00003 1.65 1.6e-05 -0.000699 -0.005527</pose>
          <velocity>0 2e-06 -5.6e-05 5e-05 -1e-06 0.000142</velocity>
          <acceleration>0.000757 -0.003743 -0.062406 0.00037 -1.1e-05 -2.8e-05</acceleration>
          <wrench>0.0227 -0.112277 -1.87217 0 -0 0</wrench>
        </link>
      </model>
    </state>
    <gui fullscreen='0'>
      <camera name='user_camera'>
        <pose>20.7749 -10.4567 9.75769 0 0.351643 2.72419</pose>
        <view_controller>orbit</view_controller>
      </camera>
    </gui>
    <model name='ragdoll'>
      <pose>-2 -8 1.4 0 -0 0</pose>
      <link name='hip'>
        <inertial>
          <inertia>
            <ixx>0.1</ixx>
            <ixy>0</ixy>
            <ixz>0</ixz>
            <iyy>0.1</iyy>
            <iyz>0</iyz>
            <izz>0.1</izz>
          </inertia>
          <mass>10</mass>
        </inertial>
        <collision name='hip_geom'>
          <pose>0 0 0.125 0 -0 0</pose>
          <geometry>
            <box>
              <size>0.1 0.5 0.25</size>
            </box>
          </geometry>
          <surface>
            <friction>
              <ode>
                <mu>-1</mu>
                <mu2>-1</mu2>
                <fdir1>0 0 0</fdir1>
                <slip1>0</slip1>
                <slip2>0</slip2>
              </ode>
            </friction>
            <bounce>
              <restitution_coefficient>0</restitution_coefficient>
              <threshold>100000</threshold>
            </bounce>
            <contact>
              <ode>
                <soft_cfm>0</soft_cfm>
                <soft_erp>0.2</soft_erp>
                <kp>1e+12</kp>
                <kd>1</kd>
                <max_vel>0</max_vel>
                <min_depth>0.001</min_depth>
              </ode>
            </contact>
          </surface>
          <laser_retro>0</laser_retro>
          <max_contacts>10</max_contacts>
        </collision>
        <visual name='hip_geom_visual'>
          <pose>0 0 0.125 0 -0 0</pose>
          <geometry>
            <box>
              <size>0.1 0.5 0.25</size>
            </box>
          </geometry>
          <cast_shadows>1</cast_shadows>
          <laser_retro>0</laser_retro>
          <transparency>0</transparency>
        </visual>
        <gravity>0</gravity>
        <self_collide>0</self_collide>
        <kinematic>0</kinematic>
        <velocity_decay>
          <linear>0</linear>
          <angular>0</angular>
        </velocity_decay>
      </link>
      <link name='l_thigh_pan'>
        <pose>0 0.22 0 0 -0 0</pose>
        <inertial>
          <inertia>
            <ixx>0.01</ixx>
            <ixy>0</ixy>
            <ixz>0</ixz>
            <iyy>0.01</iyy>
            <iyz>0</iyz>
            <izz>0.01</izz>
          </inertia>
          <mass>1</mass>
        </inertial>
        <collision name='l_thigh_pan_geom'>
          <pose>0 0 -0.03 0 -0 0</pose>
          <geometry>
            <sphere>
              <radius>0.06</radius>
            </sphere>
          </geometry>
          <surface>
            <friction>
              <ode>
                <mu>-1</mu>
                <mu2>-1</mu2>
                <fdir1>0 0 0</fdir1>
                <slip1>0</slip1>
                <slip2>0</slip2>
              </ode>
            </friction>
            <bounce>
              <restitution_coefficient>0</restitution_coefficient>
              <threshold>100000</threshold>
            </bounce>
            <contact>
              <ode>
                <soft_cfm>0</soft_cfm>
                <soft_erp>0.2</soft_erp>
                <kp>1e+12</kp>
                <kd>1</kd>
                <max_vel>0</max_vel>
                <min_depth>0.001</min_depth>
              </ode>
            </contact>
          </surface>
          <laser_retro>0</laser_retro>
          <max_contacts>10</max_contacts>
        </collision>
        <visual name='l_thigh_pan_geom_visual'>
          <pose>0 0 -0.03 0 -0 0</pose>
          <geometry>
            <sphere>
              <radius>0.06</radius>
            </sphere>
          </geometry>
          <cast_shadows>1</cast_shadows>
          <laser_retro>0</laser_retro>
          <transparency>0</transparency>
        </visual>
        <gravity>0</gravity>
        <self_collide>0</self_collide>
        <kinematic>0</kinematic>
        <velocity_decay>
          <linear>0</linear>
          <angular>0</angular>
        </velocity_decay>
      </link>
      <link name='l_thigh_lift'>
        <pose>0 0.22 0 0 -0 0</pose>
        <inertial>
          <inertia>
            <ixx>0.05</ixx>
            <ixy>0</ixy>
            <ixz>0</ixz>
            <iyy>0.05</iyy>
            <iyz>0</iyz>
            <izz>0.05</izz>
          </inertia>
          <mass>5</mass>
        </inertial>
        <collision name='l_thigh_lift_geom'>
          <pose>0 0 -0.35 0 -0 0</pose>
          <geometry>
            <cylinder>
              <radius>0.06</radius>
              <length>0.7</length>
            </cylinder>
          </geometry>
          <surface>
            <friction>
              <ode>
                <mu>-1</mu>
                <mu2>-1</mu2>
                <fdir1>0 0 0</fdir1>
                <slip1>0</slip1>
                <slip2>0</slip2>
              </ode>
            </friction>
            <bounce>
              <restitution_coefficient>0</restitution_coefficient>
              <threshold>100000</threshold>
            </bounce>
            <contact>
              <ode>
                <soft_cfm>0</soft_cfm>
                <soft_erp>0.2</soft_erp>
                <kp>1e+12</kp>
                <kd>1</kd>
                <max_vel>0</max_vel>
                <min_depth>0.001</min_depth>
              </ode>
            </contact>
          </surface>
          <laser_retro>0</laser_retro>
          <max_contacts>10</max_contacts>
        </collision>
        <visual name='l_thigh_lift_geom_visual'>
          <pose>0 0 -0.35 0 -0 0</pose>
          <geometry>
            <cylinder>
              <radius>0.06</radius>
              <length>0.7</length>
            </cylinder>
          </geometry>
          <cast_shadows>1</cast_shadows>
          <laser_retro>0</laser_retro>
          <transparency>0</transparency>
        </visual>
        <gravity>0</gravity>
        <self_collide>0</self_collide>
        <kinematic>0</kinematic>
        <velocity_decay>
          <linear>0</linear>
          <angular>0</angular>
        </velocity_decay>
      </link>
      <link name='l_calf'>
        <pose>0 0.22 -0.7 0 -0 0</pose>
        <inertial>
          <inertia>
            <ixx>0.02</ixx>
            <ixy>0</ixy>
            <ixz>0</ixz>
            <iyy>0.02</iyy>
            <iyz>0</iyz>
            <izz>0.02</izz>
          </inertia>
          <mass>2</mass>
        </inertial>
        <collision name='l_calf_geom'>
          <pose>0 0 -0.3 0 -0 0</pose>
          <geometry>
            <cylinder>
              <radius>0.05</radius>
              <length>0.6</length>
            </cylinder>
          </geometry>
          <surface>
            <friction>
              <ode>
                <mu>-1</mu>
                <mu2>-1</mu2>
                <fdir1>0 0 0</fdir1>
                <slip1>0</slip1>
                <slip2>0</slip2>
              </ode>
            </friction>
            <bounce>
              <restitution_coefficient>0</restitution_coefficient>
              <threshold>100000</threshold>
            </bounce>
            <contact>
              <ode>
                <soft_cfm>0</soft_cfm>
                <soft_erp>0.2</soft_erp>
                <kp>1e+12</kp>
                <kd>1</kd>
                <max_vel>0</max_vel>
                <min_depth>0.001</min_depth>
              </ode>
            </contact>
          </surface>
          <laser_retro>0</laser_retro>
          <max_contacts>10</max_contacts>
        </collision>
        <visual name='l_calf_geom_visual'>
          <pose>0 0 -0.3 0 -0 0</pose>
          <geometry>
            <cylinder>
              <radius>0.05</radius>
              <length>0.6</length>
            </cylinder>
          </geometry>
          <cast_shadows>1</cast_shadows>
          <laser_retro>0</laser_retro>
          <transparency>0</transparency>
        </visual>
        <gravity>0</gravity>
        <self_collide>0</self_collide>
        <kinematic>0</kinematic>
        <velocity_decay>
          <linear>0</linear>
          <angular>0</angular>
        </velocity_decay>
      </link>
      <link name='l_ankle'>
        <pose>0 0.22 -1.325 0 -0 0</pose>
        <inertial>
          <inertia>
            <ixx>0.01</ixx>
            <ixy>0</ixy>
            <ixz>0</ixz>
            <iyy>0.01</iyy>
            <iyz>0</iyz>
            <izz>0.01</izz>
          </inertia>
          <mass>1</mass>
        </inertial>
        <collision name='l_ankle_geom'>
          <geometry>
            <sphere>
              <radius>0.05</radius>
            </sphere>
          </geometry>
          <surface>
            <friction>
              <ode>
                <mu>-1</mu>
                <mu2>-1</mu2>
                <fdir1>0 0 0</fdir1>
                <slip1>0</slip1>
                <slip2>0</slip2>
              </ode>
            </friction>
            <bounce>
              <restitution_coefficient>0</restitution_coefficient>
              <threshold>100000</threshold>
            </bounce>
            <contact>
              <ode>
                <soft_cfm>0</soft_cfm>
                <soft_erp>0.2</soft_erp>
                <kp>1e+12</kp>
                <kd>1</kd>
                <max_vel>0</max_vel>
                <min_depth>0.001</min_depth>
              </ode>
            </contact>
          </surface>
          <laser_retro>0</laser_retro>
          <max_contacts>10</max_contacts>
        </collision>
        <visual name='l_ankle_geom_visual'>
          <geometry>
            <sphere>
              <radius>0.05</radius>
            </sphere>
          </geometry>
          <cast_shadows>1</cast_shadows>
          <laser_retro>0</laser_retro>
          <transparency>0</transparency>
        </visual>
        <gravity>0</gravity>
        <self_collide>0</self_collide>
        <kinematic>0</kinematic>
        <velocity_decay>
          <linear>0</linear>
          <angular>0</angular>
        </velocity_decay>
      </link>
      <link name='l_foot'>
        <pose>0 0.22 -1.35 0 -0 0</pose>
        <inertial>
          <pose>0.1 0 0 0 -0 0</pose>
          <inertia>
            <ixx>0.01</ixx>
            <ixy>0</ixy>
            <ixz>0</ixz>
            <iyy>0.01</iyy>
            <iyz>0</iyz>
            <izz>0.01</izz>
          </inertia>
          <mass>1</mass>
        </inertial>
        <collision name='l_foot_geom'>
          <pose>0.1 0 -0.025 0 -0 0</pose>
          <geometry>
            <box>
              <size>0.2 0.03 0.05</size>
            </box>
          </geometry>
          <surface>
            <friction>
              <ode>
                <mu>-1</mu>
                <mu2>-1</mu2>
                <fdir1>0 0 0</fdir1>
                <slip1>0</slip1>
                <slip2>0</slip2>
              </ode>
            </friction>
            <bounce>
              <restitution_coefficient>0</restitution_coefficient>
              <threshold>100000</threshold>
            </bounce>
            <contact>
              <ode>
                <soft_cfm>0</soft_cfm>
                <soft_erp>0.2</soft_erp>
                <kp>1e+12</kp>
                <kd>1</kd>
                <max_vel>0</max_vel>
                <min_depth>0.001</min_depth>
              </ode>
            </contact>
          </surface>
          <laser_retro>0</laser_retro>
          <max_contacts>10</max_contacts>
        </collision>
        <visual name='l_foot_geom_visual'>
          <pose>0.1 0 -0.025 0 -0 0</pose>
          <geometry>
            <box>
              <size>0.2 0.03 0.05</size>
            </box>
          </geometry>
          <cast_shadows>1</cast_shadows>
          <laser_retro>0</laser_retro>
          <transparency>0</transparency>
        </visual>
        <gravity>1</gravity>
        <self_collide>0</self_collide>
        <kinematic>0</kinematic>
        <velocity_decay>
          <linear>0</linear>
          <angular>0</angular>
        </velocity_decay>
      </link>
      <link name='r_thigh_pan'>
        <pose>0 -0.22 0 0 -0 0</pose>
        <inertial>
          <inertia>
            <ixx>0.01</ixx>
            <ixy>0</ixy>
            <ixz>0</ixz>
            <iyy>0.01</iyy>
            <iyz>0</iyz>
            <izz>0.01</izz>
          </inertia>
          <mass>1</mass>
        </inertial>
        <collision name='r_thigh_pan_geom'>
          <pose>0 0 -0.03 0 -0 0</pose>
          <geometry>
            <sphere>
              <radius>0.06</radius>
            </sphere>
          </geometry>
          <surface>
            <friction>
              <ode>
                <mu>-1</mu>
                <mu2>-1</mu2>
                <fdir1>0 0 0</fdir1>
                <slip1>0</slip1>
                <slip2>0</slip2>
              </ode>
            </friction>
            <bounce>
              <restitution_coefficient>0</restitution_coefficient>
              <threshold>100000</threshold>
            </bounce>
            <contact>
              <ode>
                <soft_cfm>0</soft_cfm>
                <soft_erp>0.2</soft_erp>
                <kp>1e+12</kp>
                <kd>1</kd>
                <max_vel>0</max_vel>
                <min_depth>0.001</min_depth>
              </ode>
            </contact>
          </surface>
          <laser_retro>0</laser_retro>
          <max_contacts>10</max_contacts>
        </collision>
        <visual name='r_thigh_pan_geom_visual'>
          <pose>0 0 -0.03 0 -0 0</pose>
          <geometry>
            <sphere>
              <radius>0.06</radius>
            </sphere>
          </geometry>
          <cast_shadows>1</cast_shadows>
          <laser_retro>0</laser_retro>
          <transparency>0</transparency>
        </visual>
        <gravity>0</gravity>
        <self_collide>0</self_collide>
        <kinematic>0</kinematic>
        <velocity_decay>
          <linear>0</linear>
          <angular>0</angular>
        </velocity_decay>
      </link>
      <link name='r_thigh_lift'>
        <pose>0 -0.22 0 0 -0 0</pose>
        <inertial>
          <inertia>
            <ixx>0.05</ixx>
            <ixy>0</ixy>
            <ixz>0</ixz>
            <iyy>0.05</iyy>
            <iyz>0</iyz>
            <izz>0.05</izz>
          </inertia>
          <mass>5</mass>
        </inertial>
        <collision name='r_thigh_lift_geom'>
          <pose>0 0 -0.35 0 -0 0</pose>
          <geometry>
            <cylinder>
              <radius>0.06</radius>
              <length>0.7</length>
            </cylinder>
          </geometry>
          <surface>
            <friction>
              <ode>
                <mu>-1</mu>
                <mu2>-1</mu2>
                <fdir1>0 0 0</fdir1>
                <slip1>0</slip1>
                <slip2>0</slip2>
              </ode>
            </friction>
            <bounce>
              <restitution_coefficient>0</restitution_coefficient>
              <threshold>100000</threshold>
            </bounce>
            <contact>
              <ode>
                <soft_cfm>0</soft_cfm>
                <soft_erp>0.2</soft_erp>
                <kp>1e+12</kp>
                <kd>1</kd>
                <max_vel>0</max_vel>
                <min_depth>0.001</min_depth>
              </ode>
            </contact>
          </surface>
          <laser_retro>0</laser_retro>
          <max_contacts>10</max_contacts>
        </collision>
        <visual name='r_thigh_lift_geom_visual'>
          <pose>0 0 -0.35 0 -0 0</pose>
          <geometry>
            <cylinder>
              <radius>0.06</radius>
              <length>0.7</length>
            </cylinder>
          </geometry>
          <cast_shadows>1</cast_shadows>
          <laser_retro>0</laser_retro>
          <transparency>0</transparency>
        </visual>
        <gravity>0</gravity>
        <self_collide>0</self_collide>
        <kinematic>0</kinematic>
        <velocity_decay>
          <linear>0</linear>
          <angular>0</angular>
        </velocity_decay>
      </link>
      <link name='r_calf'>
        <pose>0 -0.22 -0.7 0 -0 0</pose>
        <inertial>
          <inertia>
            <ixx>0.02</ixx>
            <ixy>0</ixy>
            <ixz>0</ixz>
            <iyy>0.02</iyy>
            <iyz>0</iyz>
            <izz>0.02</izz>
          </inertia>
          <mass>2</mass>
        </inertial>
        <collision name='r_calf_geom'>
          <pose>0 0 -0.3 0 -0 0</pose>
          <geometry>
            <cylinder>
              <radius>0.05</radius>
              <length>0.6</length>
            </cylinder>
          </geometry>
          <surface>
            <friction>
              <ode>
                <mu>-1</mu>
                <mu2>-1</mu2>
                <fdir1>0 0 0</fdir1>
                <slip1>0</slip1>
                <slip2>0</slip2>
              </ode>
            </friction>
            <bounce>
              <restitution_coefficient>0</restitution_coefficient>
              <threshold>100000</threshold>
            </bounce>
            <contact>
              <ode>
                <soft_cfm>0</soft_cfm>
                <soft_erp>0.2</soft_erp>
                <kp>1e+12</kp>
                <kd>1</kd>
                <max_vel>0</max_vel>
                <min_depth>0.001</min_depth>
              </ode>
            </contact>
          </surface>
          <laser_retro>0</laser_retro>
          <max_contacts>10</max_contacts>
        </collision>
        <visual name='r_calf_geom_visual'>
          <pose>0 0 -0.3 0 -0 0</pose>
          <geometry>
            <cylinder>
              <radius>0.05</radius>
              <length>0.6</length>
            </cylinder>
          </geometry>
          <cast_shadows>1</cast_shadows>
          <laser_retro>0</laser_retro>
          <transparency>0</transparency>
        </visual>
        <gravity>0</gravity>
        <self_collide>0</self_collide>
        <kinematic>0</kinematic>
        <velocity_decay>
          <linear>0</linear>
          <angular>0</angular>
        </velocity_decay>
      </link>
      <link name='r_ankle'>
        <pose>0 -0.22 -1.325 0 -0 0</pose>
        <inertial>
          <inertia>
            <ixx>0.01</ixx>
            <ixy>0</ixy>
            <ixz>0</ixz>
            <iyy>0.01</iyy>
            <iyz>0</iyz>
            <izz>0.01</izz>
          </inertia>
          <mass>1</mass>
        </inertial>
        <collision name='r_ankle_geom'>
          <geometry>
            <sphere>
              <radius>0.05</radius>
            </sphere>
          </geometry>
          <surface>
            <friction>
              <ode>
                <mu>-1</mu>
                <mu2>-1</mu2>
                <fdir1>0 0 0</fdir1>
                <slip1>0</slip1>
                <slip2>0</slip2>
              </ode>
            </friction>
            <bounce>
              <restitution_coefficient>0</restitution_coefficient>
              <threshold>100000</threshold>
            </bounce>
            <contact>
              <ode>
                <soft_cfm>0</soft_cfm>
                <soft_erp>0.2</soft_erp>
                <kp>1e+12</kp>
                <kd>1</kd>
                <max_vel>0</max_vel>
                <min_depth>0.001</min_depth>
              </ode>
            </contact>
          </surface>
          <laser_retro>0</laser_retro>
          <max_contacts>10</max_contacts>
        </collision>
        <visual name='r_ankle_geom_visual'>
          <geometry>
            <sphere>
              <radius>0.05</radius>
            </sphere>
          </geometry>
          <cast_shadows>1</cast_shadows>
          <laser_retro>0</laser_retro>
          <transparency>0</transparency>
        </visual>
        <gravity>0</gravity>
        <self_collide>0</self_collide>
        <kinematic>0</kinematic>
        <velocity_decay>
          <linear>0</linear>
          <angular>0</angular>
        </velocity_decay>
      </link>
      <link name='r_foot'>
        <pose>0 -0.22 -1.35 0 -0 0</pose>
        <inertial>
          <pose>0.1 0 0 0 -0 0</pose>
          <inertia>
            <ixx>0.01</ixx>
            <ixy>0</ixy>
            <ixz>0</ixz>
            <iyy>0.01</iyy>
            <iyz>0</iyz>
            <izz>0.01</izz>
          </inertia>
          <mass>1</mass>
        </inertial>
        <collision name='r_foot_geom'>
          <pose>0.1 0 -0.025 0 -0 0</pose>
          <geometry>
            <box>
              <size>0.2 0.03 0.05</size>
            </box>
          </geometry>
          <surface>
            <friction>
              <ode>
                <mu>-1</mu>
                <mu2>-1</mu2>
                <fdir1>0 0 0</fdir1>
                <slip1>0</slip1>
                <slip2>0</slip2>
              </ode>
            </friction>
            <bounce>
              <restitution_coefficient>0</restitution_coefficient>
              <threshold>100000</threshold>
            </bounce>
            <contact>
              <ode>
                <soft_cfm>0</soft_cfm>
                <soft_erp>0.2</soft_erp>
                <kp>1e+12</kp>
                <kd>1</kd>
                <max_vel>0</max_vel>
                <min_depth>0.001</min_depth>
              </ode>
            </contact>
          </surface>
          <laser_retro>0</laser_retro>
          <max_contacts>10</max_contacts>
        </collision>
        <visual name='r_foot_geom_visual'>
          <pose>0.1 0 -0.025 0 -0 0</pose>
          <geometry>
            <box>
              <size>0.2 0.03 0.05</size>
            </box>
          </geometry>
          <cast_shadows>1</cast_shadows>
          <laser_retro>0</laser_retro>
          <transparency>0</transparency>
        </visual>
        <gravity>1</gravity>
        <self_collide>0</self_collide>
        <kinematic>0</kinematic>
        <velocity_decay>
          <linear>0</linear>
          <angular>0</angular>
        </velocity_decay>
      </link>
      <link name='torso'>
        <pose>0 0 0.25 0 -0 0</pose>
        <inertial>
          <inertia>
            <ixx>0.3</ixx>
            <ixy>0</ixy>
            <ixz>0</ixz>
            <iyy>0.3</iyy>
            <iyz>0</iyz>
            <izz>0.3</izz>
          </inertia>
          <mass>30</mass>
        </inertial>
        <collision name='torso_geom'>
          <pose>0 0 0.35 0 -0 0</pose>
          <geometry>
            <box>
              <size>0.1 0.6 0.7</size>
            </box>
          </geometry>
          <surface>
            <friction>
              <ode>
                <mu>-1</mu>
                <mu2>-1</mu2>
                <fdir1>0 0 0</fdir1>
                <slip1>0</slip1>
                <slip2>0</slip2>
              </ode>
            </friction>
            <bounce>
              <restitution_coefficient>0</restitution_coefficient>
              <threshold>100000</threshold>
            </bounce>
            <contact>
              <ode>
                <soft_cfm>0</soft_cfm>
                <soft_erp>0.2</soft_erp>
                <kp>1e+12</kp>
                <kd>1</kd>
                <max_vel>0</max_vel>
                <min_depth>0.001</min_depth>
              </ode>
            </contact>
          </surface>
          <laser_retro>0</laser_retro>
          <max_contacts>10</max_contacts>
        </collision>
        <visual name='torso_geom_visual'>
          <pose>0 0 0.35 0 -0 0</pose>
          <geometry>
            <box>
              <size>0.1 0.6 0.7</size>
            </box>
          </geometry>
          <cast_shadows>1</cast_shadows>
          <laser_retro>0</laser_retro>
          <transparency>0</transparency>
        </visual>
        <gravity>0</gravity>
        <self_collide>0</self_collide>
        <kinematic>0</kinematic>
        <velocity_decay>
          <linear>0</linear>
          <angular>0</angular>
        </velocity_decay>
      </link>
      <link name='l_shoulder'>
        <pose>0 0.3275 0.9225 0 -0 0</pose>
        <inertial>
          <inertia>
            <ixx>0.01</ixx>
            <ixy>0</ixy>
            <ixz>0</ixz>
            <iyy>0.01</iyy>
            <iyz>0</iyz>
            <izz>0.01</izz>
          </inertia>
          <mass>1</mass>
        </inertial>
        <collision name='l_shoulder_geom'>
          <geometry>
            <sphere>
              <radius>0.055</radius>
            </sphere>
          </geometry>
          <surface>
            <friction>
              <ode>
                <mu>-1</mu>
                <mu2>-1</mu2>
                <fdir1>0 0 0</fdir1>
                <slip1>0</slip1>
                <slip2>0</slip2>
              </ode>
            </friction>
            <bounce>
              <restitution_coefficient>0</restitution_coefficient>
              <threshold>100000</threshold>
            </bounce>
            <contact>
              <ode>
                <soft_cfm>0</soft_cfm>
                <soft_erp>0.2</soft_erp>
                <kp>1e+12</kp>
                <kd>1</kd>
                <max_vel>0</max_vel>
                <min_depth>0.001</min_depth>
              </ode>
            </contact>
          </surface>
          <laser_retro>0</laser_retro>
          <max_contacts>10</max_contacts>
        </collision>
        <visual name='l_shoulder_geom_visual'>
          <geometry>
            <sphere>
              <radius>0.055</radius>
            </sphere>
          </geometry>
          <cast_shadows>1</cast_shadows>
          <laser_retro>0</laser_retro>
          <transparency>0</transparency>
        </visual>
        <gravity>0</gravity>
        <self_collide>0</self_collide>
        <kinematic>0</kinematic>
        <velocity_decay>
          <linear>0</linear>
          <angular>0</angular>
        </velocity_decay>
      </link>
      <link name='l_upper_arm'>
        <pose>0 0.3275 0.9225 0 -0 0</pose>
        <inertial>
          <inertia>
            <ixx>0.02</ixx>
            <ixy>0</ixy>
            <ixz>0</ixz>
            <iyy>0.02</iyy>
            <iyz>0</iyz>
            <izz>0.02</izz>
          </inertia>
          <mass>2</mass>
        </inertial>
        <collision name='l_upper_arm_geom'>
          <pose>0 0 -0.3 0 -0 0</pose>
          <geometry>
            <cylinder>
              <radius>0.055</radius>
              <length>0.6</length>
            </cylinder>
          </geometry>
          <surface>
            <friction>
              <ode>
                <mu>-1</mu>
                <mu2>-1</mu2>
                <fdir1>0 0 0</fdir1>
                <slip1>0</slip1>
                <slip2>0</slip2>
              </ode>
            </friction>
            <bounce>
              <restitution_coefficient>0</restitution_coefficient>
              <threshold>100000</threshold>
            </bounce>
            <contact>
              <ode>
                <soft_cfm>0</soft_cfm>
                <soft_erp>0.2</soft_erp>
                <kp>1e+12</kp>
                <kd>1</kd>
                <max_vel>0</max_vel>
                <min_depth>0.001</min_depth>
              </ode>
            </contact>
          </surface>
          <laser_retro>0</laser_retro>
          <max_contacts>10</max_contacts>
        </collision>
        <visual name='l_upper_arm_geom_visual'>
          <pose>0 0 -0.3 0 -0 0</pose>
          <geometry>
            <cylinder>
              <radius>0.055</radius>
              <length>0.6</length>
            </cylinder>
          </geometry>
          <cast_shadows>1</cast_shadows>
          <laser_retro>0</laser_retro>
          <transparency>0</transparency>
        </visual>
        <gravity>0</gravity>
        <self_collide>0</self_collide>
        <kinematic>0</kinematic>
        <velocity_decay>
          <linear>0</linear>
          <angular>0</angular>
        </velocity_decay>
      </link>
      <link name='l_forearm'>
        <pose>0 0.3275 0.3225 0 -0 0</pose>
        <inertial>
          <inertia>
            <ixx>0.01</ixx>
            <ixy>0</ixy>
            <ixz>0</ixz>
            <iyy>0.01</iyy>
            <iyz>0</iyz>
            <izz>0.01</izz>
          </inertia>
          <mass>1</mass>
        </inertial>
        <collision name='l_forearm_geom'>
          <pose>0 0 -0.225 0 -0 0</pose>
          <geometry>
            <cylinder>
              <radius>0.05</radius>
              <length>0.45</length>
            </cylinder>
          </geometry>
          <surface>
            <friction>
              <ode>
                <mu>-1</mu>
                <mu2>-1</mu2>
                <fdir1>0 0 0</fdir1>
                <slip1>0</slip1>
                <slip2>0</slip2>
              </ode>
            </friction>
            <bounce>
              <restitution_coefficient>0</restitution_coefficient>
              <threshold>100000</threshold>
            </bounce>
            <contact>
              <ode>
                <soft_cfm>0</soft_cfm>
                <soft_erp>0.2</soft_erp>
                <kp>1e+12</kp>
                <kd>1</kd>
                <max_vel>0</max_vel>
                <min_depth>0.001</min_depth>
              </ode>
            </contact>
          </surface>
          <laser_retro>0</laser_retro>
          <max_contacts>10</max_contacts>
        </collision>
        <visual name='l_forearm_geom_visual'>
          <pose>0 0 -0.225 0 -0 0</pose>
          <geometry>
            <cylinder>
              <radius>0.05</radius>
              <length>0.45</length>
            </cylinder>
          </geometry>
          <cast_shadows>1</cast_shadows>
          <laser_retro>0</laser_retro>
          <transparency>0</transparency>
        </visual>
        <gravity>0</gravity>
        <self_collide>0</self_collide>
        <kinematic>0</kinematic>
        <velocity_decay>
          <linear>0</linear>
          <angular>0</angular>
        </velocity_decay>
      </link>
      <link name='l_wrist'>
        <pose>0 0.3275 -0.1425 0 -0 0</pose>
        <inertial>
          <inertia>
            <ixx>0.01</ixx>
            <ixy>0</ixy>
            <ixz>0</ixz>
            <iyy>0.01</iyy>
            <iyz>0</iyz>
            <izz>0.01</izz>
          </inertia>
          <mass>1</mass>
        </inertial>
        <collision name='l_wrist_geom'>
          <geometry>
            <sphere>
              <radius>0.03</radius>
            </sphere>
          </geometry>
          <surface>
            <friction>
              <ode>
                <mu>-1</mu>
                <mu2>-1</mu2>
                <fdir1>0 0 0</fdir1>
                <slip1>0</slip1>
                <slip2>0</slip2>
              </ode>
            </friction>
            <bounce>
              <restitution_coefficient>0</restitution_coefficient>
              <threshold>100000</threshold>
            </bounce>
            <contact>
              <ode>
                <soft_cfm>0</soft_cfm>
                <soft_erp>0.2</soft_erp>
                <kp>1e+12</kp>
                <kd>1</kd>
                <max_vel>0</max_vel>
                <min_depth>0.001</min_depth>
              </ode>
            </contact>
          </surface>
          <laser_retro>0</laser_retro>
          <max_contacts>10</max_contacts>
        </collision>
        <visual name='l_wrist_geom_visual'>
          <geometry>
            <sphere>
              <radius>0.03</radius>
            </sphere>
          </geometry>
          <cast_shadows>1</cast_shadows>
          <laser_retro>0</laser_retro>
          <transparency>0</transparency>
        </visual>
        <gravity>0</gravity>
        <self_collide>0</self_collide>
        <kinematic>0</kinematic>
        <velocity_decay>
          <linear>0</linear>
          <angular>0</angular>
        </velocity_decay>
      </link>
      <link name='l_hand'>
        <pose>0 0.3275 -0.1575 0 -0 0</pose>
        <inertial>
          <inertia>
            <ixx>0.01</ixx>
            <ixy>0</ixy>
            <ixz>0</ixz>
            <iyy>0.01</iyy>
            <iyz>0</iyz>
            <izz>0.01</izz>
          </inertia>
          <mass>1</mass>
        </inertial>
        <collision name='l_hand_geom'>
          <pose>0 0 -0.1 0 -0 0</pose>
          <geometry>
            <box>
              <size>0.03 0.1 0.2</size>
            </box>
          </geometry>
          <surface>
            <friction>
              <ode>
                <mu>-1</mu>
                <mu2>-1</mu2>
                <fdir1>0 0 0</fdir1>
                <slip1>0</slip1>
                <slip2>0</slip2>
              </ode>
            </friction>
            <bounce>
              <restitution_coefficient>0</restitution_coefficient>
              <threshold>100000</threshold>
            </bounce>
            <contact>
              <ode>
                <soft_cfm>0</soft_cfm>
                <soft_erp>0.2</soft_erp>
                <kp>1e+12</kp>
                <kd>1</kd>
                <max_vel>0</max_vel>
                <min_depth>0.001</min_depth>
              </ode>
            </contact>
          </surface>
          <laser_retro>0</laser_retro>
          <max_contacts>10</max_contacts>
        </collision>
        <visual name='l_hand_geom_visual'>
          <pose>0 0 -0.1 0 -0 0</pose>
          <geometry>
            <box>
              <size>0.03 0.1 0.2</size>
            </box>
          </geometry>
          <cast_shadows>1</cast_shadows>
          <laser_retro>0</laser_retro>
          <transparency>0</transparency>
        </visual>
        <gravity>0</gravity>
        <self_collide>0</self_collide>
        <kinematic>0</kinematic>
        <velocity_decay>
          <linear>0</linear>
          <angular>0</angular>
        </velocity_decay>
      </link>
      <link name='neck'>
        <pose>0 0 0.95 0 -0 0</pose>
        <inertial>
          <inertia>
            <ixx>0.01</ixx>
            <ixy>0</ixy>
            <ixz>0</ixz>
            <iyy>0.01</iyy>
            <iyz>0</iyz>
            <izz>0.01</izz>
          </inertia>
          <mass>1</mass>
        </inertial>
        <collision name='neck_geom'>
          <pose>0 0 0.1 0 -0 0</pose>
          <geometry>
            <cylinder>
              <radius>0.075</radius>
              <length>0.2</length>
            </cylinder>
          </geometry>
          <surface>
            <friction>
              <ode>
                <mu>-1</mu>
                <mu2>-1</mu2>
                <fdir1>0 0 0</fdir1>
                <slip1>0</slip1>
                <slip2>0</slip2>
              </ode>
            </friction>
            <bounce>
              <restitution_coefficient>0</restitution_coefficient>
              <threshold>100000</threshold>
            </bounce>
            <contact>
              <ode>
                <soft_cfm>0</soft_cfm>
                <soft_erp>0.2</soft_erp>
                <kp>1e+12</kp>
                <kd>1</kd>
                <max_vel>0</max_vel>
                <min_depth>0.001</min_depth>
              </ode>
            </contact>
          </surface>
          <laser_retro>0</laser_retro>
          <max_contacts>10</max_contacts>
        </collision>
        <visual name='neck_geom_visual'>
          <pose>0 0 0.1 0 -0 0</pose>
          <geometry>
            <cylinder>
              <radius>0.075</radius>
              <length>0.2</length>
            </cylinder>
          </geometry>
          <cast_shadows>1</cast_shadows>
          <laser_retro>0</laser_retro>
          <transparency>0</transparency>
        </visual>
        <gravity>0</gravity>
        <self_collide>0</self_collide>
        <kinematic>0</kinematic>
        <velocity_decay>
          <linear>0</linear>
          <angular>0</angular>
        </velocity_decay>
      </link>
      <link name='head'>
        <pose>0 0 1.225 0 -0 0</pose>
        <inertial>
          <inertia>
            <ixx>0.1</ixx>
            <ixy>0</ixy>
            <ixz>0</ixz>
            <iyy>0.1</iyy>
            <iyz>0</iyz>
            <izz>0.1</izz>
          </inertia>
          <mass>10</mass>
        </inertial>
        <collision name='head_geom'>
          <geometry>
            <sphere>
              <radius>0.15</radius>
            </sphere>
          </geometry>
          <surface>
            <friction>
              <ode>
                <mu>-1</mu>
                <mu2>-1</mu2>
                <fdir1>0 0 0</fdir1>
                <slip1>0</slip1>
                <slip2>0</slip2>
              </ode>
            </friction>
            <bounce>
              <restitution_coefficient>0</restitution_coefficient>
              <threshold>100000</threshold>
            </bounce>
            <contact>
              <ode>
                <soft_cfm>0</soft_cfm>
                <soft_erp>0.2</soft_erp>
                <kp>1e+12</kp>
                <kd>1</kd>
                <max_vel>0</max_vel>
                <min_depth>0.001</min_depth>
              </ode>
            </contact>
          </surface>
          <laser_retro>0</laser_retro>
          <max_contacts>10</max_contacts>
        </collision>
        <visual name='head_geom_visual'>
          <geometry>
            <sphere>
              <radius>0.15</radius>
            </sphere>
          </geometry>
          <cast_shadows>1</cast_shadows>
          <laser_retro>0</laser_retro>
          <transparency>0</transparency>
        </visual>
        <gravity>0</gravity>
        <self_collide>0</self_collide>
        <kinematic>0</kinematic>
        <velocity_decay>
          <linear>0</linear>
          <angular>0</angular>
        </velocity_decay>
      </link>
      <link name='r_shoulder'>
        <pose>0 -0.3275 0.9225 0 -0 0</pose>
        <inertial>
          <inertia>
            <ixx>0.01</ixx>
            <ixy>0</ixy>
            <ixz>0</ixz>
            <iyy>0.01</iyy>
            <iyz>0</iyz>
            <izz>0.01</izz>
          </inertia>
          <mass>1</mass>
        </inertial>
        <collision name='r_shoulder_geom'>
          <geometry>
            <sphere>
              <radius>0.055</radius>
            </sphere>
          </geometry>
          <surface>
            <friction>
              <ode>
                <mu>-1</mu>
                <mu2>-1</mu2>
                <fdir1>0 0 0</fdir1>
                <slip1>0</slip1>
                <slip2>0</slip2>
              </ode>
            </friction>
            <bounce>
              <restitution_coefficient>0</restitution_coefficient>
              <threshold>100000</threshold>
            </bounce>
            <contact>
              <ode>
                <soft_cfm>0</soft_cfm>
                <soft_erp>0.2</soft_erp>
                <kp>1e+12</kp>
                <kd>1</kd>
                <max_vel>0</max_vel>
                <min_depth>0.001</min_depth>
              </ode>
            </contact>
          </surface>
          <laser_retro>0</laser_retro>
          <max_contacts>10</max_contacts>
        </collision>
        <visual name='r_shoulder_geom_visual'>
          <geometry>
            <sphere>
              <radius>0.055</radius>
            </sphere>
          </geometry>
          <cast_shadows>1</cast_shadows>
          <laser_retro>0</laser_retro>
          <transparency>0</transparency>
        </visual>
        <gravity>0</gravity>
        <self_collide>0</self_collide>
        <kinematic>0</kinematic>
        <velocity_decay>
          <linear>0</linear>
          <angular>0</angular>
        </velocity_decay>
      </link>
      <link name='r_upper_arm'>
        <pose>0 -0.3275 0.9225 0 -0 0</pose>
        <inertial>
          <inertia>
            <ixx>0.02</ixx>
            <ixy>0</ixy>
            <ixz>0</ixz>
            <iyy>0.02</iyy>
            <iyz>0</iyz>
            <izz>0.02</izz>
          </inertia>
          <mass>2</mass>
        </inertial>
        <collision name='r_upper_arm_geom'>
          <pose>0 0 -0.3 0 -0 0</pose>
          <geometry>
            <cylinder>
              <radius>0.055</radius>
              <length>0.6</length>
            </cylinder>
          </geometry>
          <surface>
            <friction>
              <ode>
                <mu>-1</mu>
                <mu2>-1</mu2>
                <fdir1>0 0 0</fdir1>
                <slip1>0</slip1>
                <slip2>0</slip2>
              </ode>
            </friction>
            <bounce>
              <restitution_coefficient>0</restitution_coefficient>
              <threshold>100000</threshold>
            </bounce>
            <contact>
              <ode>
                <soft_cfm>0</soft_cfm>
                <soft_erp>0.2</soft_erp>
                <kp>1e+12</kp>
                <kd>1</kd>
                <max_vel>0</max_vel>
                <min_depth>0.001</min_depth>
              </ode>
            </contact>
          </surface>
          <laser_retro>0</laser_retro>
          <max_contacts>10</max_contacts>
        </collision>
        <visual name='r_upper_arm_geom_visual'>
          <pose>0 0 -0.3 0 -0 0</pose>
          <geometry>
            <cylinder>
              <radius>0.055</radius>
              <length>0.6</length>
            </cylinder>
          </geometry>
          <cast_shadows>1</cast_shadows>
          <laser_retro>0</laser_retro>
          <transparency>0</transparency>
        </visual>
        <gravity>0</gravity>
        <self_collide>0</self_collide>
        <kinematic>0</kinematic>
        <velocity_decay>
          <linear>0</linear>
          <angular>0</angular>
        </velocity_decay>
      </link>
      <link name='r_forearm'>
        <pose>0 -0.3275 0.3225 0 -0 0</pose>
        <inertial>
          <inertia>
            <ixx>0.01</ixx>
            <ixy>0</ixy>
            <ixz>0</ixz>
            <iyy>0.01</iyy>
            <iyz>0</iyz>
            <izz>0.01</izz>
          </inertia>
          <mass>1</mass>
        </inertial>
        <collision name='r_forearm_geom'>
          <pose>0 0 -0.225 0 -0 0</pose>
          <geometry>
            <cylinder>
              <radius>0.05</radius>
              <length>0.45</length>
            </cylinder>
          </geometry>
          <surface>
            <friction>
              <ode>
                <mu>-1</mu>
                <mu2>-1</mu2>
                <fdir1>0 0 0</fdir1>
                <slip1>0</slip1>
                <slip2>0</slip2>
              </ode>
            </friction>
            <bounce>
              <restitution_coefficient>0</restitution_coefficient>
              <threshold>100000</threshold>
            </bounce>
            <contact>
              <ode>
                <soft_cfm>0</soft_cfm>
                <soft_erp>0.2</soft_erp>
                <kp>1e+12</kp>
                <kd>1</kd>
                <max_vel>0</max_vel>
                <min_depth>0.001</min_depth>
              </ode>
            </contact>
          </surface>
          <laser_retro>0</laser_retro>
          <max_contacts>10</max_contacts>
        </collision>
        <visual name='r_forearm_geom_visual'>
          <pose>0 0 -0.225 0 -0 0</pose>
          <geometry>
            <cylinder>
              <radius>0.05</radius>
              <length>0.45</length>
            </cylinder>
          </geometry>
          <cast_shadows>1</cast_shadows>
          <laser_retro>0</laser_retro>
          <transparency>0</transparency>
        </visual>
        <gravity>0</gravity>
        <self_collide>0</self_collide>
        <kinematic>0</kinematic>
        <velocity_decay>
          <linear>0</linear>
          <angular>0</angular>
        </velocity_decay>
      </link>
      <link name='r_wrist'>
        <pose>0 -0.3275 -0.1425 0 -0 0</pose>
        <inertial>
          <inertia>
            <ixx>0.01</ixx>
            <ixy>0</ixy>
            <ixz>0</ixz>
            <iyy>0.01</iyy>
            <iyz>0</iyz>
            <izz>0.01</izz>
          </inertia>
          <mass>1</mass>
        </inertial>
        <collision name='r_wrist_geom'>
          <geometry>
            <sphere>
              <radius>0.03</radius>
            </sphere>
          </geometry>
          <surface>
            <friction>
              <ode>
                <mu>-1</mu>
                <mu2>-1</mu2>
                <fdir1>0 0 0</fdir1>
                <slip1>0</slip1>
                <slip2>0</slip2>
              </ode>
            </friction>
            <bounce>
              <restitution_coefficient>0</restitution_coefficient>
              <threshold>100000</threshold>
            </bounce>
            <contact>
              <ode>
                <soft_cfm>0</soft_cfm>
                <soft_erp>0.2</soft_erp>
                <kp>1e+12</kp>
                <kd>1</kd>
                <max_vel>0</max_vel>
                <min_depth>0.001</min_depth>
              </ode>
            </contact>
          </surface>
          <laser_retro>0</laser_retro>
          <max_contacts>10</max_contacts>
        </collision>
        <visual name='r_wrist_geom_visual'>
          <geometry>
            <sphere>
              <radius>0.03</radius>
            </sphere>
          </geometry>
          <cast_shadows>1</cast_shadows>
          <laser_retro>0</laser_retro>
          <transparency>0</transparency>
        </visual>
        <gravity>0</gravity>
        <self_collide>0</self_collide>
        <kinematic>0</kinematic>
        <velocity_decay>
          <linear>0</linear>
          <angular>0</angular>
        </velocity_decay>
      </link>
      <link name='r_hand'>
        <pose>0 -0.3275 -0.1575 0 -0 0</pose>
        <inertial>
          <inertia>
            <ixx>0.01</ixx>
            <ixy>0</ixy>
            <ixz>0</ixz>
            <iyy>0.01</iyy>
            <iyz>0</iyz>
            <izz>0.01</izz>
          </inertia>
          <mass>1</mass>
        </inertial>
        <collision name='r_hand_geom'>
          <pose>0 0 -0.1 0 -0 0</pose>
          <geometry>
            <box>
              <size>0.03 0.1 0.2</size>
            </box>
          </geometry>
          <surface>
            <friction>
              <ode>
                <mu>-1</mu>
                <mu2>-1</mu2>
                <fdir1>0 0 0</fdir1>
                <slip1>0</slip1>
                <slip2>0</slip2>
              </ode>
            </friction>
            <bounce>
              <restitution_coefficient>0</restitution_coefficient>
              <threshold>100000</threshold>
            </bounce>
            <contact>
              <ode>
                <soft_cfm>0</soft_cfm>
                <soft_erp>0.2</soft_erp>
                <kp>1e+12</kp>
                <kd>1</kd>
                <max_vel>0</max_vel>
                <min_depth>0.001</min_depth>
              </ode>
            </contact>
          </surface>
          <laser_retro>0</laser_retro>
          <max_contacts>10</max_contacts>
        </collision>
        <visual name='r_hand_geom_visual'>
          <pose>0 0 -0.1 0 -0 0</pose>
          <geometry>
            <box>
              <size>0.03 0.1 0.2</size>
            </box>
          </geometry>
          <cast_shadows>1</cast_shadows>
          <laser_retro>0</laser_retro>
          <transparency>0</transparency>
        </visual>
        <gravity>0</gravity>
        <self_collide>0</self_collide>
        <kinematic>0</kinematic>
        <velocity_decay>
          <linear>0</linear>
          <angular>0</angular>
        </velocity_decay>
      </link>
      <joint name='l_thigh_pan_joint' type='revolute'>
        <parent>hip</parent>
        <child>l_thigh_pan</child>
        <axis>
          <dynamics>
            <damping>0</damping>
            <friction>0</friction>
          </dynamics>
          <limit>
            <lower>-1.5708</lower>
            <upper>1.5708</upper>
            <effort>0</effort>
            <velocity>0</velocity>
          </limit>
          <xyz>0 0 1</xyz>
        </axis>
      </joint>
      <joint name='l_thigh_lift_joint' type='revolute'>
        <parent>l_thigh_pan</parent>
        <child>l_thigh_lift</child>
        <axis>
          <dynamics>
            <damping>0</damping>
            <friction>0</friction>
          </dynamics>
          <limit>
            <lower>-1.5708</lower>
            <upper>1.5708</upper>
            <effort>0</effort>
            <velocity>0</velocity>
          </limit>
          <xyz>0 1 0</xyz>
        </axis>
      </joint>
      <joint name='l_calf_joint' type='revolute'>
        <parent>l_thigh_lift</parent>
        <child>l_calf</child>
        <axis>
          <dynamics>
            <damping>0</damping>
            <friction>0</friction>
          </dynamics>
          <limit>
            <lower>-1.5708</lower>
            <upper>1.5708</upper>
            <effort>0</effort>
            <velocity>0</velocity>
          </limit>
          <xyz>0 1 0</xyz>
        </axis>
      </joint>
      <joint name='l_ankle_joint' type='revolute'>
        <parent>l_calf</parent>
        <child>l_ankle</child>
        <axis>
          <dynamics>
            <damping>0</damping>
            <friction>0</friction>
          </dynamics>
          <limit>
            <lower>-1.5708</lower>
            <upper>1.5708</upper>
            <effort>0</effort>
            <velocity>0</velocity>
          </limit>
          <xyz>0 1 0</xyz>
        </axis>
      </joint>
      <joint name='l_foot_joint' type='revolute'>
        <parent>l_ankle</parent>
        <child>l_foot</child>
        <axis>
          <dynamics>
            <damping>0</damping>
            <friction>0</friction>
          </dynamics>
          <limit>
            <lower>-1.5708</lower>
            <upper>1.5708</upper>
            <effort>0</effort>
            <velocity>0</velocity>
          </limit>
          <xyz>1 0 0</xyz>
        </axis>
      </joint>
      <joint name='r_thigh_pan_joint' type='revolute'>
        <parent>hip</parent>
        <child>r_thigh_pan</child>
        <axis>
          <dynamics>
            <damping>0</damping>
            <friction>0</friction>
          </dynamics>
          <limit>
            <lower>-1.5708</lower>
            <upper>1.5708</upper>
            <effort>0</effort>
            <velocity>0</velocity>
          </limit>
          <xyz>0 0 1</xyz>
        </axis>
      </joint>
      <joint name='r_thigh_lift_joint' type='revolute'>
        <parent>r_thigh_pan</parent>
        <child>r_thigh_lift</child>
        <axis>
          <dynamics>
            <damping>0</damping>
            <friction>0</friction>
          </dynamics>
          <limit>
            <lower>-1.5708</lower>
            <upper>1.5708</upper>
            <effort>0</effort>
            <velocity>0</velocity>
          </limit>
          <xyz>0 1 0</xyz>
        </axis>
      </joint>
      <joint name='r_calf_joint' type='revolute'>
        <parent>r_thigh_lift</parent>
        <child>r_calf</child>
        <axis>
          <dynamics>
            <damping>0</damping>
            <friction>0</friction>
          </dynamics>
          <limit>
            <lower>-1.5708</lower>
            <upper>1.5708</upper>
            <effort>0</effort>
            <velocity>0</velocity>
          </limit>
          <xyz>0 1 0</xyz>
        </axis>
      </joint>
      <joint name='r_ankle_joint' type='revolute'>
        <parent>r_calf</parent>
        <child>r_ankle</child>
        <axis>
          <dynamics>
            <damping>0</damping>
            <friction>0</friction>
          </dynamics>
          <limit>
            <lower>-1.5708</lower>
            <upper>1.5708</upper>
            <effort>0</effort>
            <velocity>0</velocity>
          </limit>
          <xyz>0 1 0</xyz>
        </axis>
      </joint>
      <joint name='r_foot_joint' type='revolute'>
        <parent>r_ankle</parent>
        <child>r_foot</child>
        <axis>
          <dynamics>
            <damping>0</damping>
            <friction>0</friction>
          </dynamics>
          <limit>
            <lower>-1.5708</lower>
            <upper>1.5708</upper>
            <effort>0</effort>
            <velocity>0</velocity>
          </limit>
          <xyz>1 0 0</xyz>
        </axis>
      </joint>
      <joint name='torso_joint' type='revolute'>
        <parent>hip</parent>
        <child>torso</child>
        <axis>
          <dynamics>
            <damping>0</damping>
            <friction>0</friction>
          </dynamics>
          <limit>
            <lower>-1.5708</lower>
            <upper>1.5708</upper>
            <effort>0</effort>
            <velocity>0</velocity>
          </limit>
          <xyz>0 1 0</xyz>
        </axis>
      </joint>
      <joint name='l_shoulder_joint' type='revolute'>
        <parent>torso</parent>
        <child>l_shoulder</child>
        <axis>
          <dynamics>
            <damping>0</damping>
            <friction>0</friction>
          </dynamics>
          <limit>
            <lower>-1.5708</lower>
            <upper>1.5708</upper>
            <effort>0</effort>
            <velocity>0</velocity>
          </limit>
          <xyz>1 0 0</xyz>
        </axis>
      </joint>
      <joint name='l_upper_arm_joint' type='revolute'>
        <parent>l_shoulder</parent>
        <child>l_upper_arm</child>
        <axis>
          <dynamics>
            <damping>0</damping>
            <friction>0</friction>
          </dynamics>
          <limit>
            <lower>-1.5708</lower>
            <upper>1.5708</upper>
            <effort>0</effort>
            <velocity>0</velocity>
          </limit>
          <xyz>0 1 0</xyz>
        </axis>
      </joint>
      <joint name='l_forearm_joint' type='revolute'>
        <parent>l_upper_arm</parent>
        <child>l_forearm</child>
        <axis>
          <dynamics>
            <damping>0</damping>
            <friction>0</friction>
          </dynamics>
          <limit>
            <lower>-1.5708</lower>
            <upper>1.5708</upper>
            <effort>0</effort>
            <velocity>0</velocity>
          </limit>
          <xyz>0 1 0</xyz>
        </axis>
      </joint>
      <joint name='l_wrist_joint' type='revolute'>
        <parent>l_forearm</parent>
        <child>l_wrist</child>
        <axis>
          <dynamics>
            <damping>0</damping>
            <friction>0</friction>
          </dynamics>
          <limit>
            <lower>-1.5708</lower>
            <upper>1.5708</upper>
            <effort>0</effort>
            <velocity>0</velocity>
          </limit>
          <xyz>0 1 0</xyz>
        </axis>
      </joint>
      <joint name='l_hand_joint' type='revolute'>
        <parent>l_wrist</parent>
        <child>l_hand</child>
        <axis>
          <dynamics>
            <damping>0</damping>
            <friction>0</friction>
          </dynamics>
          <limit>
            <lower>-1.5708</lower>
            <upper>1.5708</upper>
            <effort>0</effort>
            <velocity>0</velocity>
          </limit>
          <xyz>0 1 0</xyz>
        </axis>
      </joint>
      <joint name='neck_joint' type='revolute'>
        <parent>torso</parent>
        <child>neck</child>
        <axis>
          <dynamics>
            <damping>0</damping>
            <friction>0</friction>
          </dynamics>
          <limit>
            <lower>-1.5708</lower>
            <upper>1.5708</upper>
            <effort>0</effort>
            <velocity>0</velocity>
          </limit>
          <xyz>0 0 1</xyz>
        </axis>
      </joint>
      <joint name='head_joint' type='revolute'>
        <parent>neck</parent>
        <child>head</child>
        <axis>
          <dynamics>
            <damping>0</damping>
            <friction>0</friction>
          </dynamics>
          <limit>
            <lower>-1.5708</lower>
            <upper>1.5708</upper>
            <effort>0</effort>
            <velocity>0</velocity>
          </limit>
          <xyz>0 1 0</xyz>
        </axis>
      </joint>
      <joint name='r_shoulder_joint' type='revolute'>
        <parent>torso</parent>
        <child>r_shoulder</child>
        <axis>
          <dynamics>
            <damping>0</damping>
            <friction>0</friction>
          </dynamics>
          <limit>
            <lower>-1.5708</lower>
            <upper>1.5708</upper>
            <effort>0</effort>
            <velocity>0</velocity>
          </limit>
          <xyz>1 0 0</xyz>
        </axis>
      </joint>
      <joint name='r_upper_arm_joint' type='revolute'>
        <parent>r_shoulder</parent>
        <child>r_upper_arm</child>
        <axis>
          <dynamics>
            <damping>0</damping>
            <friction>0</friction>
          </dynamics>
          <limit>
            <lower>-1.5708</lower>
            <upper>1.5708</upper>
            <effort>0</effort>
            <velocity>0</velocity>
          </limit>
          <xyz>0 1 0</xyz>
        </axis>
      </joint>
      <joint name='r_forearm_joint' type='revolute'>
        <parent>r_upper_arm</parent>
        <child>r_forearm</child>
        <axis>
          <dynamics>
            <damping>0</damping>
            <friction>0</friction>
          </dynamics>
          <limit>
            <lower>-1.5708</lower>
            <upper>1.5708</upper>
            <effort>0</effort>
            <velocity>0</velocity>
          </limit>
          <xyz>0 1 0</xyz>
        </axis>
      </joint>
      <joint name='r_wrist_joint' type='revolute'>
        <parent>r_forearm</parent>
        <child>r_wrist</child>
        <axis>
          <dynamics>
            <damping>0</damping>
            <friction>0</friction>
          </dynamics>
          <limit>
            <lower>-1.5708</lower>
            <upper>1.5708</upper>
            <effort>0</effort>
            <velocity>0</velocity>
          </limit>
          <xyz>0 1 0</xyz>
        </axis>
      </joint>
      <joint name='r_hand_joint' type='revolute'>
        <parent>r_wrist</parent>
        <child>r_hand</child>
        <axis>
          <dynamics>
            <damping>0</damping>
            <friction>0</friction>
          </dynamics>
          <limit>
            <lower>-1.5708</lower>
            <upper>1.5708</upper>
            <effort>0</effort>
            <velocity>0</velocity>
          </limit>
          <xyz>0 1 0</xyz>
        </axis>
      </joint>
      <static>0</static>
    </model>
    <model name='Stop Sign'>
      <link name='link'>
        <collision name='collision'>
          <geometry>
            <mesh>
              <uri>model://stop_sign/meshes/stop_sign.dae</uri>
            </mesh>
          </geometry>
          <max_contacts>10</max_contacts>
          <surface>
            <bounce/>
            <friction>
              <ode/>
            </friction>
            <contact>
              <ode/>
            </contact>
          </surface>
        </collision>
        <visual name='visual'>
          <geometry>
            <mesh>
              <uri>model://stop_sign/meshes/stop_sign.dae</uri>
            </mesh>
          </geometry>
          <material>
            <script>
              <uri>model://stop_sign/materials/scripts</uri>
              <uri>model://stop_sign/materials/textures</uri>
              <name>StopSign/Diffuse</name>
            </script>
          </material>
        </visual>
        <velocity_decay>
          <linear>0</linear>
          <angular>0</angular>
        </velocity_decay>
        <self_collide>0</self_collide>
        <inertial>
          <inertia>
            <ixx>1</ixx>
            <ixy>0</ixy>
            <ixz>0</ixz>
            <iyy>1</iyy>
            <iyz>0</iyz>
            <izz>1</izz>
          </inertia>
          <mass>1</mass>
        </inertial>
        <kinematic>0</kinematic>
        <gravity>1</gravity>
      </link>
      <pose>3.52624 4 0 0 -0 0</pose>
      <static>0</static>
    </model>
    <model name='Speed limit'>
      <static>1</static>
      <link name='link'>
        <collision name='collision'>
          <geometry>
            <mesh>
              <scale>10 10 10</scale>
              <uri>model://speed_limit_sign/meshes/speed_limit_sign.dae</uri>
            </mesh>
          </geometry>
          <max_contacts>10</max_contacts>
          <surface>
            <bounce/>
            <friction>
              <ode/>
            </friction>
            <contact>
              <ode/>
            </contact>
          </surface>
        </collision>
        <visual name='visual'>
          <geometry>
            <mesh>
              <scale>10 10 10</scale>
              <uri>model://speed_limit_sign/meshes/speed_limit_sign.dae</uri>
            </mesh>
          </geometry>
        </visual>
        <velocity_decay>
          <linear>0</linear>
          <angular>0</angular>
        </velocity_decay>
        <self_collide>0</self_collide>
        <kinematic>0</kinematic>
        <gravity>1</gravity>
      </link>
      <pose>-2 -9 0 0 -0 0</pose>
    </model>
    <model name='polaris_ranger_ev'>
      <link name='chassis'>
        <inertial>
          <mass>720</mass>
          <inertia>
            <ixx>140</ixx>
            <ixy>0</ixy>
            <iyy>550</iyy>
            <ixz>0</ixz>
            <iyz>0</iyz>
            <izz>550</izz>
          </inertia>
          <pose>0.1 0 0.4 0 -0 0</pose>
        </inertial>
        <visual name='visual'>
          <pose>0 0 0 0 0 -1.5708</pose>
          <geometry>
            <mesh>
              <uri>model://polaris_ranger_ev/meshes/polaris.dae</uri>
              <submesh>
                <name>Ranger</name>
                <center>0</center>
              </submesh>
            </mesh>
          </geometry>
          <material>
            <script>
              <uri>model://polaris_ranger_ev/materials/scripts</uri>
              <uri>model://polaris_ranger_ev/materials/textures</uri>
              <name>Polaris/Diffuse</name>
            </script>
          </material>
        </visual>
        <collision name='chassis_bottom'>
          <pose>0.1 0 0.37 0 -0 0</pose>
          <geometry>
            <box>
              <size>1.5 1.34 0.06</size>
            </box>
          </geometry>
          <max_contacts>10</max_contacts>
          <surface>
            <bounce/>
            <friction>
              <ode/>
            </friction>
            <contact>
              <ode/>
            </contact>
          </surface>
        </collision>
        <collision name='cargo_bottom'>
          <pose>-0.9 0 0.9 0 -0 0</pose>
          <geometry>
            <box>
              <size>0.9 1.2 0.01</size>
            </box>
          </geometry>
          <max_contacts>10</max_contacts>
          <surface>
            <bounce/>
            <friction>
              <ode/>
            </friction>
            <contact>
              <ode/>
            </contact>
          </surface>
        </collision>
        <collision name='cargo_front'>
          <pose>-0.45 0 1.025 0 -0 0</pose>
          <geometry>
            <box>
              <size>0.05 1.2 0.25</size>
            </box>
          </geometry>
          <max_contacts>10</max_contacts>
          <surface>
            <bounce/>
            <friction>
              <ode/>
            </friction>
            <contact>
              <ode/>
            </contact>
          </surface>
        </collision>
        <collision name='cargo_back'>
          <pose>-1.35 0 1.025 0 -0 0</pose>
          <geometry>
            <box>
              <size>0.05 1.2 0.25</size>
            </box>
          </geometry>
          <max_contacts>10</max_contacts>
          <surface>
            <bounce/>
            <friction>
              <ode/>
            </friction>
            <contact>
              <ode/>
            </contact>
          </surface>
        </collision>
        <collision name='cargo_left'>
          <pose>-0.9 0.6 1.025 0 -0 0</pose>
          <geometry>
            <box>
              <size>0.9 0.05 0.25</size>
            </box>
          </geometry>
          <max_contacts>10</max_contacts>
          <surface>
            <bounce/>
            <friction>
              <ode/>
            </friction>
            <contact>
              <ode/>
            </contact>
          </surface>
        </collision>
        <collision name='cargo_right'>
          <pose>-0.9 -0.6 1.025 0 -0 0</pose>
          <geometry>
            <box>
              <size>0.9 0.05 0.25</size>
            </box>
          </geometry>
          <max_contacts>10</max_contacts>
          <surface>
            <bounce/>
            <friction>
              <ode/>
            </friction>
            <contact>
              <ode/>
            </contact>
          </surface>
        </collision>
        <collision name='seat'>
          <pose>-0.1 0 0.56 0 -0 0</pose>
          <geometry>
            <box>
              <size>0.6 1.22 0.5</size>
            </box>
          </geometry>
          <surface>
            <contact>
              <ode>
                <min_depth>0.01</min_depth>
              </ode>
            </contact>
            <bounce/>
            <friction>
              <ode/>
            </friction>
          </surface>
          <max_contacts>10</max_contacts>
        </collision>
        <collision name='mud_seat'>
          <pose>-0.1 0 0.81 0 -0 0</pose>
          <geometry>
            <box>
              <size>0.6 1.15 0.1</size>
            </box>
          </geometry>
          <surface>
            <contact>
              <collide_without_contact>1</collide_without_contact>
              <ode/>
            </contact>
            <bounce/>
            <friction>
              <ode/>
            </friction>
          </surface>
          <max_contacts>10</max_contacts>
        </collision>
        <sensor name='seat_contact' type='contact'>
          <always_on>1</always_on>
          <update_rate>1000</update_rate>
          <contact>
            <collision>mud_seat</collision>
            <topic>__default_topic__</topic>
          </contact>
        </sensor>
        <collision name='seat_back'>
          <pose>-0.3 0 1.125 0 -0.2 0</pose>
          <geometry>
            <box>
              <size>0.06 1 0.4</size>
            </box>
          </geometry>
          <max_contacts>10</max_contacts>
          <surface>
            <bounce/>
            <friction>
              <ode/>
            </friction>
            <contact>
              <ode/>
            </contact>
          </surface>
        </collision>
        <collision name='engine'>
          <pose>1.05 0 0.7 0 -0 0</pose>
          <geometry>
            <box>
              <size>0.58 1 0.8</size>
            </box>
          </geometry>
          <max_contacts>10</max_contacts>
          <surface>
            <bounce/>
            <friction>
              <ode/>
            </friction>
            <contact>
              <ode/>
            </contact>
          </surface>
        </collision>
        <collision name='handle_left_middle'>
          <pose>-0.3 0.61 1.055 0 -0.2 0</pose>
          <geometry>
            <cylinder>
              <radius>0.02</radius>
              <length>0.17</length>
            </cylinder>
          </geometry>
          <max_contacts>10</max_contacts>
          <surface>
            <bounce/>
            <friction>
              <ode/>
            </friction>
            <contact>
              <ode/>
            </contact>
          </surface>
        </collision>
        <collision name='handle_right_middle'>
          <pose>-0.3 -0.61 1.055 0 -0.2 0</pose>
          <geometry>
            <cylinder>
              <radius>0.02</radius>
              <length>0.17</length>
            </cylinder>
          </geometry>
          <max_contacts>10</max_contacts>
          <surface>
            <bounce/>
            <friction>
              <ode/>
            </friction>
            <contact>
              <ode/>
            </contact>
          </surface>
        </collision>
        <collision name='rollcage_top_left'>
          <pose>0 0.61 1.92 3.14159 1.53159 3.14159</pose>
          <geometry>
            <cylinder>
              <radius>0.03</radius>
              <length>0.68</length>
            </cylinder>
          </geometry>
          <max_contacts>10</max_contacts>
          <surface>
            <bounce/>
            <friction>
              <ode/>
            </friction>
            <contact>
              <ode/>
            </contact>
          </surface>
        </collision>
        <collision name='rollcage_top_right'>
          <pose>0 -0.61 1.92 3.14159 1.53159 3.14159</pose>
          <geometry>
            <cylinder>
              <radius>0.03</radius>
              <length>0.68</length>
            </cylinder>
          </geometry>
          <max_contacts>10</max_contacts>
          <surface>
            <bounce/>
            <friction>
              <ode/>
            </friction>
            <contact>
              <ode/>
            </contact>
          </surface>
        </collision>
        <collision name='rollcage_top_front'>
          <pose>0.325 0 1.89 1.5708 -0 0</pose>
          <geometry>
            <cylinder>
              <radius>0.03</radius>
              <length>1.22</length>
            </cylinder>
          </geometry>
          <max_contacts>10</max_contacts>
          <surface>
            <bounce/>
            <friction>
              <ode/>
            </friction>
            <contact>
              <ode/>
            </contact>
          </surface>
        </collision>
        <collision name='rollcage_top_back'>
          <pose>-0.33 0 1.92 1.5708 -0 0</pose>
          <geometry>
            <cylinder>
              <radius>0.03</radius>
              <length>1.22</length>
            </cylinder>
          </geometry>
          <max_contacts>10</max_contacts>
          <surface>
            <bounce/>
            <friction>
              <ode/>
            </friction>
            <contact>
              <ode/>
            </contact>
          </surface>
        </collision>
        <collision name='rollcage_front_left'>
          <pose>0.54 0.61 1.45 0 -0.44 0</pose>
          <geometry>
            <cylinder>
              <radius>0.03</radius>
              <length>1.04</length>
            </cylinder>
          </geometry>
          <max_contacts>10</max_contacts>
          <surface>
            <bounce/>
            <friction>
              <ode/>
            </friction>
            <contact>
              <ode/>
            </contact>
          </surface>
        </collision>
        <collision name='rollcage_front_right'>
          <pose>0.54 -0.61 1.45 0 -0.44 0</pose>
          <geometry>
            <cylinder>
              <radius>0.03</radius>
              <length>1.04</length>
            </cylinder>
          </geometry>
          <max_contacts>10</max_contacts>
          <surface>
            <bounce/>
            <friction>
              <ode/>
            </friction>
            <contact>
              <ode/>
            </contact>
          </surface>
        </collision>
        <collision name='fender_front_right'>
          <pose>0.64 -0.61 0.7 0 0.35 0</pose>
          <geometry>
            <cylinder>
              <radius>0.03</radius>
              <length>0.72</length>
            </cylinder>
          </geometry>
          <max_contacts>10</max_contacts>
          <surface>
            <bounce/>
            <friction>
              <ode/>
            </friction>
            <contact>
              <ode/>
            </contact>
          </surface>
        </collision>
        <collision name='fender_front_left'>
          <pose>0.64 0.61 0.7 0 0.35 0</pose>
          <geometry>
            <cylinder>
              <radius>0.03</radius>
              <length>0.72</length>
            </cylinder>
          </geometry>
          <max_contacts>10</max_contacts>
          <surface>
            <bounce/>
            <friction>
              <ode/>
            </friction>
            <contact>
              <ode/>
            </contact>
          </surface>
        </collision>
        <collision name='rollcage_back_left'>
          <pose>-0.37 0.61 1.25 0 -0.14 0</pose>
          <geometry>
            <cylinder>
              <radius>0.03</radius>
              <length>0.9</length>
            </cylinder>
          </geometry>
          <max_contacts>10</max_contacts>
          <surface>
            <bounce/>
            <friction>
              <ode/>
            </friction>
            <contact>
              <ode/>
            </contact>
          </surface>
        </collision>
        <collision name='rollcage_back_right'>
          <pose>-0.37 -0.61 1.25 0 -0.14 0</pose>
          <geometry>
            <cylinder>
              <radius>0.03</radius>
              <length>0.9</length>
            </cylinder>
          </geometry>
          <max_contacts>10</max_contacts>
          <surface>
            <bounce/>
            <friction>
              <ode/>
            </friction>
            <contact>
              <ode/>
            </contact>
          </surface>
        </collision>
        <collision name='rollcage_back_midleft'>
          <pose>-0.37 0.155 1.25 0 -0.14 0</pose>
          <geometry>
            <cylinder>
              <radius>0.023</radius>
              <length>0.9</length>
            </cylinder>
          </geometry>
          <max_contacts>10</max_contacts>
          <surface>
            <bounce/>
            <friction>
              <ode/>
            </friction>
            <contact>
              <ode/>
            </contact>
          </surface>
        </collision>
        <collision name='rollcage_back_midright'>
          <pose>-0.37 -0.155 1.25 0 -0.14 0</pose>
          <geometry>
            <cylinder>
              <radius>0.023</radius>
              <length>0.9</length>
            </cylinder>
          </geometry>
          <max_contacts>10</max_contacts>
          <surface>
            <bounce/>
            <friction>
              <ode/>
            </friction>
            <contact>
              <ode/>
            </contact>
          </surface>
        </collision>
        <collision name='rollcage_back_upper_left'>
          <pose>-0.38 0.61 1.82 0 0.4 0</pose>
          <geometry>
            <cylinder>
              <radius>0.03</radius>
              <length>0.29</length>
            </cylinder>
          </geometry>
          <max_contacts>10</max_contacts>
          <surface>
            <bounce/>
            <friction>
              <ode/>
            </friction>
            <contact>
              <ode/>
            </contact>
          </surface>
        </collision>
        <collision name='rollcage_back_upper_right'>
          <pose>-0.38 -0.61 1.82 0 0.4 0</pose>
          <geometry>
            <cylinder>
              <radius>0.03</radius>
              <length>0.29</length>
            </cylinder>
          </geometry>
          <max_contacts>10</max_contacts>
          <surface>
            <bounce/>
            <friction>
              <ode/>
            </friction>
            <contact>
              <ode/>
            </contact>
          </surface>
        </collision>
        <collision name='rollcage_back_upper_midleft'>
          <pose>-0.38 0.155 1.82 0 0.4 0</pose>
          <geometry>
            <cylinder>
              <radius>0.023</radius>
              <length>0.29</length>
            </cylinder>
          </geometry>
          <max_contacts>10</max_contacts>
          <surface>
            <bounce/>
            <friction>
              <ode/>
            </friction>
            <contact>
              <ode/>
            </contact>
          </surface>
        </collision>
        <collision name='rollcage_back_upper_midright'>
          <pose>-0.38 -0.155 1.82 0 0.4 0</pose>
          <geometry>
            <cylinder>
              <radius>0.023</radius>
              <length>0.29</length>
            </cylinder>
          </geometry>
          <max_contacts>10</max_contacts>
          <surface>
            <bounce/>
            <friction>
              <ode/>
            </friction>
            <contact>
              <ode/>
            </contact>
          </surface>
        </collision>
        <velocity_decay>
          <linear>0</linear>
          <angular>0</angular>
        </velocity_decay>
        <self_collide>0</self_collide>
        <kinematic>0</kinematic>
        <gravity>1</gravity>
      </link>
      <link name='rear_right_wheel'>
        <pose>-0.85 -0.6 0.32 1.52 -0 0</pose>
        <inertial>
          <mass>12</mass>
          <inertia>
            <ixx>0.5</ixx>
            <ixy>0</ixy>
            <iyy>0.5</iyy>
            <ixz>0</ixz>
            <iyz>0</iyz>
            <izz>1</izz>
          </inertia>
        </inertial>
        <collision name='collision'>
          <geometry>
            <cylinder>
              <radius>0.32</radius>
              <length>0.23</length>
            </cylinder>
          </geometry>
          <max_contacts>1</max_contacts>
          <surface>
            <friction>
              <ode>
                <mu>1</mu>
                <mu2>1</mu2>
                <fdir1>0 0 1</fdir1>
                <slip1>0</slip1>
                <slip2>0</slip2>
              </ode>
            </friction>
            <contact>
              <ode>
                <min_depth>0.005</min_depth>
                <kp>1e+08</kp>
              </ode>
            </contact>
            <bounce/>
          </surface>
        </collision>
        <visual name='visual'>
          <pose>0 0 0 3.14159 -1.57079 3.14159</pose>
          <geometry>
            <mesh>
              <uri>model://polaris_ranger_ev/meshes/polaris.dae</uri>
              <submesh>
                <name>Rear_Wheel_Right</name>
                <center>1</center>
              </submesh>
            </mesh>
          </geometry>
          <material>
            <script>
              <uri>model://polaris_ranger_ev/materials/scripts</uri>
              <uri>model://polaris_ranger_ev/materials/textures</uri>
              <name>Polaris/Diffuse</name>
            </script>
          </material>
        </visual>
        <velocity_decay>
          <linear>0</linear>
          <angular>0</angular>
        </velocity_decay>
        <self_collide>0</self_collide>
        <kinematic>0</kinematic>
        <gravity>1</gravity>
      </link>
      <link name='rear_left_wheel'>
        <pose>-0.85 0.6 0.32 -1.52 0 0</pose>
        <inertial>
          <mass>12</mass>
          <inertia>
            <ixx>0.5</ixx>
            <ixy>0</ixy>
            <iyy>0.5</iyy>
            <ixz>0</ixz>
            <iyz>0</iyz>
            <izz>1</izz>
          </inertia>
        </inertial>
        <collision name='collision'>
          <geometry>
            <cylinder>
              <radius>0.32</radius>
              <length>0.23</length>
            </cylinder>
          </geometry>
          <max_contacts>1</max_contacts>
          <surface>
            <friction>
              <ode>
                <mu>1</mu>
                <mu2>1</mu2>
                <fdir1>0 0 1</fdir1>
                <slip1>0</slip1>
                <slip2>0</slip2>
              </ode>
            </friction>
            <contact>
              <ode>
                <min_depth>0.005</min_depth>
                <kp>1e+08</kp>
              </ode>
            </contact>
            <bounce/>
          </surface>
        </collision>
        <visual name='visual'>
          <pose>0 0 0 3.14159 -1.57079 3.14159</pose>
          <geometry>
            <mesh>
              <uri>model://polaris_ranger_ev/meshes/polaris.dae</uri>
              <submesh>
                <name>Rear_Wheel_Left</name>
                <center>1</center>
              </submesh>
            </mesh>
          </geometry>
          <material>
            <script>
              <uri>model://polaris_ranger_ev/materials/scripts</uri>
              <uri>model://polaris_ranger_ev/materials/textures</uri>
              <name>Polaris/Diffuse</name>
            </script>
          </material>
        </visual>
        <velocity_decay>
          <linear>0</linear>
          <angular>0</angular>
        </velocity_decay>
        <self_collide>0</self_collide>
        <kinematic>0</kinematic>
        <gravity>1</gravity>
      </link>
      <link name='front_right_wheel'>
        <pose>1.03 -0.6 0.32 1.52 -0 0</pose>
        <inertial>
          <mass>12</mass>
          <inertia>
            <ixx>0.5</ixx>
            <ixy>0</ixy>
            <iyy>0.5</iyy>
            <ixz>0</ixz>
            <iyz>0</iyz>
            <izz>1</izz>
          </inertia>
        </inertial>
        <collision name='collision'>
          <geometry>
            <cylinder>
              <radius>0.32</radius>
              <length>0.23</length>
            </cylinder>
          </geometry>
          <max_contacts>1</max_contacts>
          <surface>
            <friction>
              <ode>
                <mu>1</mu>
                <mu2>1</mu2>
                <fdir1>0 0 1</fdir1>
                <slip1>0</slip1>
                <slip2>0</slip2>
              </ode>
            </friction>
            <contact>
              <ode>
                <min_depth>0.005</min_depth>
                <kp>1e+08</kp>
              </ode>
            </contact>
            <bounce/>
          </surface>
        </collision>
        <visual name='visual'>
          <pose>0 0 0 3.14159 -1.57079 3.14159</pose>
          <geometry>
            <mesh>
              <uri>model://polaris_ranger_ev/meshes/polaris.dae</uri>
              <submesh>
                <name>Front_Wheel_Right</name>
                <center>1</center>
              </submesh>
            </mesh>
          </geometry>
          <material>
            <script>
              <uri>model://polaris_ranger_ev/materials/scripts</uri>
              <uri>model://polaris_ranger_ev/materials/textures</uri>
              <name>Polaris/Diffuse</name>
            </script>
          </material>
        </visual>
        <velocity_decay>
          <linear>0</linear>
          <angular>0</angular>
        </velocity_decay>
        <self_collide>0</self_collide>
        <kinematic>0</kinematic>
        <gravity>1</gravity>
      </link>
      <link name='front_right_wheel_steering_block'>
        <pose>1.03 -0.5 0.32 1.5708 -0 0</pose>
        <inertial>
          <mass>1</mass>
          <inertia>
            <ixx>1</ixx>
            <ixy>0</ixy>
            <iyy>1</iyy>
            <ixz>0</ixz>
            <iyz>0</iyz>
            <izz>1</izz>
          </inertia>
        </inertial>
        <collision name='collision'>
          <geometry>
            <cylinder>
              <radius>0.05</radius>
              <length>0.01</length>
            </cylinder>
          </geometry>
          <max_contacts>10</max_contacts>
          <surface>
            <bounce/>
            <friction>
              <ode/>
            </friction>
            <contact>
              <ode/>
            </contact>
          </surface>
        </collision>
        <velocity_decay>
          <linear>0</linear>
          <angular>0</angular>
        </velocity_decay>
        <self_collide>0</self_collide>
        <kinematic>0</kinematic>
        <gravity>1</gravity>
      </link>
      <link name='front_left_wheel'>
        <pose>1.03 0.6 0.32 -1.52 0 0</pose>
        <inertial>
          <mass>12</mass>
          <inertia>
            <ixx>0.5</ixx>
            <ixy>0</ixy>
            <iyy>0.5</iyy>
            <ixz>0</ixz>
            <iyz>0</iyz>
            <izz>1</izz>
          </inertia>
        </inertial>
        <collision name='collision'>
          <geometry>
            <cylinder>
              <radius>0.32</radius>
              <length>0.23</length>
            </cylinder>
          </geometry>
          <max_contacts>1</max_contacts>
          <surface>
            <friction>
              <ode>
                <mu>1</mu>
                <mu2>1</mu2>
                <fdir1>0 0 1</fdir1>
                <slip1>0</slip1>
                <slip2>0</slip2>
              </ode>
            </friction>
            <contact>
              <ode>
                <min_depth>0.005</min_depth>
                <kp>1e+08</kp>
              </ode>
            </contact>
            <bounce/>
          </surface>
        </collision>
        <visual name='visual'>
          <pose>0 0 0 -2.65359e-06 1.57079 3.14159</pose>
          <geometry>
            <mesh>
              <uri>model://polaris_ranger_ev/meshes/polaris.dae</uri>
              <submesh>
                <name>Front_Wheel_Left</name>
                <center>1</center>
              </submesh>
            </mesh>
          </geometry>
          <material>
            <script>
              <uri>model://polaris_ranger_ev/materials/scripts</uri>
              <uri>model://polaris_ranger_ev/materials/textures</uri>
              <name>Polaris/Diffuse</name>
            </script>
          </material>
        </visual>
        <velocity_decay>
          <linear>0</linear>
          <angular>0</angular>
        </velocity_decay>
        <self_collide>0</self_collide>
        <kinematic>0</kinematic>
        <gravity>1</gravity>
      </link>
      <link name='front_left_wheel_steering_block'>
        <pose>1.03 0.5 0.32 1.5708 -0 0</pose>
        <inertial>
          <mass>1</mass>
          <inertia>
            <ixx>1</ixx>
            <ixy>0</ixy>
            <iyy>1</iyy>
            <ixz>0</ixz>
            <iyz>0</iyz>
            <izz>1</izz>
          </inertia>
        </inertial>
        <collision name='collision'>
          <geometry>
            <cylinder>
              <radius>0.05</radius>
              <length>0.01</length>
            </cylinder>
          </geometry>
          <max_contacts>10</max_contacts>
          <surface>
            <bounce/>
            <friction>
              <ode/>
            </friction>
            <contact>
              <ode/>
            </contact>
          </surface>
        </collision>
        <velocity_decay>
          <linear>0</linear>
          <angular>0</angular>
        </velocity_decay>
        <self_collide>0</self_collide>
        <kinematic>0</kinematic>
        <gravity>1</gravity>
      </link>
      <link name='gas_pedal'>
        <pose>0.63 0.1 0.58 0 -0 0</pose>
        <gravity>0</gravity>
        <inertial>
          <mass>0.1</mass>
          <pose>0 0 0 0 -0 0</pose>
          <inertia>
            <ixx>0.01</ixx>
            <ixy>0</ixy>
            <ixz>0</ixz>
            <iyy>0.01</iyy>
            <iyz>0</iyz>
            <izz>0.01</izz>
          </inertia>
        </inertial>
        <collision name='gas_pedal_collision'>
          <pose>-0.0385 0 -0.086 3.14159 1.12559 3.14159</pose>
          <geometry>
            <box>
              <size>0.1069 0.077 0.01</size>
            </box>
          </geometry>
          <max_contacts>10</max_contacts>
          <surface>
            <bounce/>
            <friction>
              <ode/>
            </friction>
            <contact>
              <ode/>
            </contact>
          </surface>
        </collision>
        <visual name='visual'>
          <pose>0 0 0 0 0 -1.5707</pose>
          <geometry>
            <mesh>
              <uri>model://polaris_ranger_ev/meshes/polaris.dae</uri>
              <submesh>
                <name>Pedal_Gas</name>
                <center>1</center>
              </submesh>
            </mesh>
          </geometry>
          <material>
            <script>
              <uri>model://polaris_ranger_ev/materials/scripts</uri>
              <uri>model://polaris_ranger_ev/materials/textures</uri>
              <name>Polaris/Diffuse</name>
            </script>
          </material>
        </visual>
        <velocity_decay>
          <linear>0</linear>
          <angular>0</angular>
        </velocity_decay>
        <self_collide>0</self_collide>
        <kinematic>0</kinematic>
      </link>
      <link name='brake_pedal'>
        <gravity>0</gravity>
        <pose>0.64 0.27 0.58 0 -0 0</pose>
        <inertial>
          <mass>0.1</mass>
          <pose>0 0 0 0 -0 0</pose>
          <inertia>
            <ixx>0.01</ixx>
            <ixy>0</ixy>
            <ixz>0</ixz>
            <iyy>0.01</iyy>
            <iyz>0</iyz>
            <izz>0.01</izz>
          </inertia>
        </inertial>
        <collision name='brake_pedal_collision'>
          <pose>-0.04 0 -0.086 3.14159 1.14259 3.14159</pose>
          <geometry>
            <box>
              <size>0.063 0.08 0.01</size>
            </box>
          </geometry>
          <max_contacts>10</max_contacts>
          <surface>
            <bounce/>
            <friction>
              <ode/>
            </friction>
            <contact>
              <ode/>
            </contact>
          </surface>
        </collision>
        <visual name='visual'>
          <pose>0 0 0 0 0 -1.5707</pose>
          <geometry>
            <mesh>
              <uri>model://polaris_ranger_ev/meshes/polaris.dae</uri>
              <submesh>
                <name>Pedal_brake</name>
                <center>1</center>
              </submesh>
            </mesh>
          </geometry>
          <material>
            <script>
              <uri>model://polaris_ranger_ev/materials/scripts</uri>
              <uri>model://polaris_ranger_ev/materials/textures</uri>
              <name>Polaris/Diffuse</name>
            </script>
          </material>
        </visual>
        <velocity_decay>
          <linear>0</linear>
          <angular>0</angular>
        </velocity_decay>
        <self_collide>0</self_collide>
        <kinematic>0</kinematic>
      </link>
      <link name='steering_wheel'>
        <pose>0.34 0.3 1.29 0 -0.87 0</pose>
        <inertial>
          <mass>1</mass>
          <pose>-0.002 0 0 0 -0 0</pose>
          <inertia>
            <ixx>0.012</ixx>
            <ixy>0</ixy>
            <ixz>0</ixz>
            <iyy>0.012</iyy>
            <iyz>0</iyz>
            <izz>0.024</izz>
          </inertia>
        </inertial>
        <collision name='collision'>
          <pose>0 0 0 -0.69 5.55112e-17 -1.5708</pose>
          <geometry>
            <mesh>
              <uri>model://polaris_ranger_ev/meshes/polaris.dae</uri>
              <submesh>
                <name>Steering_Wheel</name>
                <center>1</center>
              </submesh>
            </mesh>
          </geometry>
          <surface>
            <contact>
              <ode>
                <min_depth>0.003</min_depth>
              </ode>
            </contact>
            <bounce/>
            <friction>
              <ode/>
            </friction>
          </surface>
          <max_contacts>10</max_contacts>
        </collision>
        <visual name='visual'>
          <pose>0 0 0 -0.69 5.55112e-17 -1.5708</pose>
          <geometry>
            <mesh>
              <uri>model://polaris_ranger_ev/meshes/polaris.dae</uri>
              <submesh>
                <name>Steering_Wheel</name>
                <center>1</center>
              </submesh>
            </mesh>
          </geometry>
          <material>
            <script>
              <uri>model://polaris_ranger_ev/materials/scripts</uri>
              <uri>model://polaris_ranger_ev/materials/textures</uri>
              <name>Polaris/Diffuse</name>
            </script>
          </material>
        </visual>
        <velocity_decay>
          <linear>0</linear>
          <angular>0</angular>
        </velocity_decay>
        <self_collide>0</self_collide>
        <kinematic>0</kinematic>
        <gravity>1</gravity>
      </link>
      <link name='hand_brake'>
        <pose>0.53 0.07 1.05 0 -0 0</pose>
        <inertial>
          <mass>0.5</mass>
          <inertia>
            <ixx>0.1</ixx>
            <ixy>0</ixy>
            <ixz>0</ixz>
            <iyy>0.1</iyy>
            <iyz>0</iyz>
            <izz>0.05</izz>
          </inertia>
        </inertial>
        <collision name='hand_brake_collision'>
          <pose>0 0 0.05 -0.2 -1.38778e-17 -1.5708</pose>
          <geometry>
            <mesh>
              <uri>model://polaris_ranger_ev/meshes/polaris.dae</uri>
              <submesh>
                <name>E-Brake</name>
                <center>1</center>
              </submesh>
            </mesh>
          </geometry>
          <max_contacts>10</max_contacts>
          <surface>
            <bounce/>
            <friction>
              <ode/>
            </friction>
            <contact>
              <ode/>
            </contact>
          </surface>
        </collision>
        <visual name='hand_brake_visual'>
          <pose>0 0 0.05 -0.2 -1.38778e-17 -1.5708</pose>
          <geometry>
            <mesh>
              <uri>model://polaris_ranger_ev/meshes/polaris.dae</uri>
              <submesh>
                <name>E-Brake</name>
                <center>1</center>
              </submesh>
            </mesh>
          </geometry>
          <material>
            <script>
              <uri>model://polaris_ranger_ev/materials/scripts</uri>
              <uri>model://polaris_ranger_ev/materials/textures</uri>
              <name>Polaris/Diffuse</name>
            </script>
          </material>
        </visual>
        <velocity_decay>
          <linear>0</linear>
          <angular>0</angular>
        </velocity_decay>
        <self_collide>0</self_collide>
        <kinematic>0</kinematic>
        <gravity>1</gravity>
      </link>
      <link name='FNR_switch'>
        <pose>0.56 -0.02 1.08 0 0.25 0</pose>
        <inertial>
          <mass>0.1</mass>
          <inertia>
            <ixx>0.1</ixx>
            <ixy>0</ixy>
            <ixz>0</ixz>
            <iyy>6e-05</iyy>
            <iyz>0</iyz>
            <izz>0.1</izz>
          </inertia>
        </inertial>
        <collision name='FNR_switch'>
          <geometry>
            <box>
              <size>0.02 0.04 0.08</size>
            </box>
          </geometry>
          <max_contacts>10</max_contacts>
          <surface>
            <bounce/>
            <friction>
              <ode/>
            </friction>
            <contact>
              <ode/>
            </contact>
          </surface>
        </collision>
        <visual name='FNR_switch_F'>
          <transparency>0</transparency>
          <geometry>
            <box>
              <size>0.02 0.04 0.08</size>
            </box>
          </geometry>
          <material>
            <script>
              <uri>model://polaris_ranger_ev/materials/scripts</uri>
              <uri>model://polaris_ranger_ev/materials/textures</uri>
              <name>FNR_switch_F</name>
            </script>
          </material>
        </visual>
        <visual name='FNR_switch_R'>
          <transparency>1</transparency>
          <geometry>
            <box>
              <size>0.0199 0.0399 0.0799</size>
            </box>
          </geometry>
          <material>
            <script>
              <uri>model://polaris_ranger_ev/materials/scripts</uri>
              <uri>model://polaris_ranger_ev/materials/textures</uri>
              <name>FNR_switch_R</name>
            </script>
          </material>
        </visual>
        <velocity_decay>
          <linear>0</linear>
          <angular>0</angular>
        </velocity_decay>
        <self_collide>0</self_collide>
        <kinematic>0</kinematic>
        <gravity>1</gravity>
      </link>
      <joint name='front_left_steering_joint' type='revolute'>
        <child>front_left_wheel_steering_block</child>
        <parent>chassis</parent>
        <axis>
          <xyz>0 0 1</xyz>
          <limit>
            <lower>-0.8727</lower>
            <upper>0.8727</upper>
          </limit>
          <dynamics>
            <damping>50</damping>
          </dynamics>
        </axis>
        <physics>
          <ode>
            <cfm_damping>1</cfm_damping>
            <limit>
              <cfm>0</cfm>
              <erp>0.9</erp>
            </limit>
          </ode>
        </physics>
      </joint>
      <joint name='front_left_wheel_joint' type='revolute'>
        <child>front_left_wheel</child>
        <parent>front_left_wheel_steering_block</parent>
        <axis>
          <xyz>0 1 0.05</xyz>
          <limit>
            <lower>-1e+16</lower>
            <upper>1e+16</upper>
          </limit>
        </axis>
      </joint>
      <joint name='front_right_steering_joint' type='revolute'>
        <child>front_right_wheel_steering_block</child>
        <parent>chassis</parent>
        <axis>
          <xyz>0 0 1</xyz>
          <limit>
            <lower>-0.8727</lower>
            <upper>0.8727</upper>
          </limit>
          <dynamics>
            <damping>50</damping>
          </dynamics>
        </axis>
        <physics>
          <ode>
            <cfm_damping>1</cfm_damping>
            <limit>
              <cfm>0</cfm>
              <erp>0.9</erp>
            </limit>
          </ode>
        </physics>
      </joint>
      <joint name='front_right_wheel_joint' type='revolute'>
        <child>front_right_wheel</child>
        <parent>front_right_wheel_steering_block</parent>
        <axis>
          <xyz>0 1 -0.05</xyz>
          <limit>
            <lower>-1e+16</lower>
            <upper>1e+16</upper>
          </limit>
        </axis>
      </joint>
      <joint name='rear_left_wheel_joint' type='revolute'>
        <child>rear_left_wheel</child>
        <parent>chassis</parent>
        <axis>
          <xyz>0 1 0.05</xyz>
          <limit>
            <lower>-1e+16</lower>
            <upper>1e+16</upper>
          </limit>
        </axis>
      </joint>
      <joint name='rear_right_wheel_joint' type='revolute'>
        <pose>0 0 -0.1 0 -0 0</pose>
        <child>rear_right_wheel</child>
        <parent>chassis</parent>
        <axis>
          <xyz>0 1 -0.05</xyz>
          <limit>
            <lower>-1e+16</lower>
            <upper>1e+16</upper>
          </limit>
        </axis>
      </joint>
      <joint name='rear_differential_joint' type='revolute'>
        <child>rear_right_wheel</child>
        <parent>rear_left_wheel</parent>
        <axis>
          <xyz>0 1 0</xyz>
          <dynamics>
            <damping>70</damping>
          </dynamics>
          <limit>
            <lower>-1e+16</lower>
            <upper>1e+16</upper>
          </limit>
        </axis>
        <physics>
          <ode>
            <erp>0</erp>
            <cfm>1000</cfm>
            <cfm_damping>1</cfm_damping>
            <limit>
              <cfm>0</cfm>
              <erp>0.2</erp>
            </limit>
          </ode>
        </physics>
      </joint>
      <joint name='gas_joint' type='prismatic'>
        <parent>chassis</parent>
        <child>gas_pedal</child>
        <axis>
          <xyz>1 0 -1</xyz>
          <limit>
            <lower>0</lower>
            <upper>0.08</upper>
          </limit>
          <dynamics>
            <damping>3</damping>
          </dynamics>
        </axis>
        <physics>
          <ode>
            <cfm_damping>1</cfm_damping>
            <limit>
              <cfm>0</cfm>
              <erp>0.2</erp>
            </limit>
          </ode>
        </physics>
      </joint>
      <joint name='brake_joint' type='prismatic'>
        <parent>chassis</parent>
        <child>brake_pedal</child>
        <axis>
          <xyz>1 0 -0.6</xyz>
          <limit>
            <lower>0</lower>
            <upper>0.08</upper>
          </limit>
          <dynamics>
            <damping>3</damping>
          </dynamics>
        </axis>
        <physics>
          <ode>
            <cfm_damping>1</cfm_damping>
            <limit>
              <cfm>0</cfm>
              <erp>0.2</erp>
            </limit>
          </ode>
        </physics>
      </joint>
      <joint name='steering_joint' type='revolute'>
        <pose>-0.002 0 0 0 -0 0</pose>
        <parent>chassis</parent>
        <child>steering_wheel</child>
        <axis>
          <xyz>-1 0 0.84365</xyz>
          <limit>
            <lower>-3.14</lower>
            <upper>3.14</upper>
          </limit>
          <dynamics>
            <damping>1</damping>
          </dynamics>
        </axis>
        <physics>
          <ode>
            <cfm_damping>1</cfm_damping>
            <limit>
              <cfm>0</cfm>
              <erp>0.2</erp>
            </limit>
          </ode>
        </physics>
      </joint>
      <joint name='hand_brake_joint' type='revolute'>
        <parent>chassis</parent>
        <child>hand_brake</child>
        <axis>
          <xyz>0 -1 0</xyz>
          <limit>
            <lower>0</lower>
            <upper>0.6</upper>
          </limit>
          <dynamics>
            <damping>1</damping>
          </dynamics>
        </axis>
        <physics>
          <ode>
            <cfm_damping>1</cfm_damping>
            <limit>
              <cfm>0</cfm>
              <erp>0.2</erp>
            </limit>
          </ode>
        </physics>
      </joint>
      <joint name='FNR_switch_joint' type='revolute'>
        <parent>chassis</parent>
        <child>FNR_switch</child>
        <axis>
          <xyz>0 -1 0</xyz>
          <limit>
            <lower>-0.3</lower>
            <upper>0.3</upper>
          </limit>
          <dynamics>
            <damping>0.01</damping>
          </dynamics>
        </axis>
        <physics>
          <ode>
            <cfm_damping>1</cfm_damping>
            <limit>
              <cfm>0</cfm>
              <erp>0.2</erp>
            </limit>
          </ode>
        </physics>
      </joint>
      <pose>-6 2.55716 0 0 -0 0</pose>
      <static>0</static>
    </model>
  </world>
</sdf>
